/usr/lib/python3/dist-packages/requests/__init__.py:87: RequestsDependencyWarning: urllib3 (2.2.1) or chardet (3.0.4) doesn't match a supported version!
  warnings.warn("urllib3 ({}) or chardet ({}) doesn't match a supported "
/home/users/yz705/.local/lib/python3.10/site-packages/transformers/utils/generic.py:441: UserWarning: torch.utils._pytree._register_pytree_node is deprecated. Please use torch.utils._pytree.register_pytree_node instead.
  _torch_pytree._register_pytree_node(
/usr/lib/python3/dist-packages/requests/__init__.py:87: RequestsDependencyWarning: urllib3 (2.2.1) or chardet (3.0.4) doesn't match a supported version!
  warnings.warn("urllib3 ({}) or chardet ({}) doesn't match a supported "
wandb: Currently logged in as: ricozhu (icl-learning). Use `wandb login --relogin` to force relogin
wandb: wandb version 0.17.2 is available!  To upgrade, please run:
wandb:  $ pip install wandb --upgrade
wandb: Tracking run with wandb version 0.17.0
wandb: Run data is saved locally in /usr/project/xtmp/yz705/deep-topological-clustering/wandb/run-20240620_225239-qjcymg1u
wandb: Run `wandb offline` to turn off syncing.
wandb: Syncing run vibrant-brook-17
wandb: ‚≠êÔ∏è View project at https://wandb.ai/icl-learning/hyperparameter-sweep
wandb: üöÄ View run at https://wandb.ai/icl-learning/hyperparameter-sweep/runs/qjcymg1u
wandb: WARNING Malformed sweep config detected! This may cause your sweep to behave in unexpected ways.
wandb: WARNING To avoid this, please fix the sweep config schema violations below:
wandb: WARNING   Violation 1. lr uses log_uniform, where min/max specify base-e exponents. Use log_uniform_values to specify limit values.
wandb: WARNING Calling wandb.login() after wandb.init() has no effect.
wandb: - 0.004 MB of 0.004 MB uploadedwandb: \ 0.004 MB of 0.012 MB uploadedwandb: | 0.012 MB of 0.012 MB uploadedwandb: üöÄ View run vibrant-brook-17 at: https://wandb.ai/icl-learning/hyperparameter-sweep/runs/qjcymg1u
wandb: ‚≠êÔ∏è View project at: https://wandb.ai/icl-learning/hyperparameter-sweep
wandb: Synced 5 W&B file(s), 0 media file(s), 0 artifact file(s) and 0 other file(s)
wandb: Find logs at: ./wandb/run-20240620_225239-qjcymg1u/logs
wandb: Agent Starting Run: t0o2usnq with config:
wandb: 	epochs: 190
wandb: 	lr: 1.0011857568204294
wandb: 	new_adj_dim: 12
wandb: 	numSampledCCs: 11
wandb: 	numSampledCycles: 58
wandb: 	pretrain_epochs: 70
Exception in thread Thread-4 (_run_job):
Traceback (most recent call last):
  File "/home/users/yz705/.local/lib/python3.10/site-packages/wandb/agents/pyagent.py", line 307, in _run_job
    self._function()
  File "/usr/project/xtmp/yz705/deep-topological-clustering/./graph_autoencoder.py", line 409, in one_tune_instance
    pretrain_labels_pred, train_labels_pred = train((train_loader, adj_matrices, labels_true))
TypeError: train() missing 1 required positional argument: 'dataset'

During handling of the above exception, another exception occurred:

Traceback (most recent call last):
  File "/usr/lib/python3.10/threading.py", line 1016, in _bootstrap_inner
    self.run()
  File "/usr/lib/python3.10/threading.py", line 953, in run
    self._target(*self._args, **self._kwargs)
  File "/home/users/yz705/.local/lib/python3.10/site-packages/wandb/agents/pyagent.py", line 312, in _run_job
    wandb.finish(exit_code=1)
  File "/home/users/yz705/.local/lib/python3.10/site-packages/wandb/sdk/wandb_run.py", line 4247, in finish
    wandb.run.finish(exit_code=exit_code, quiet=quiet)
  File "/home/users/yz705/.local/lib/python3.10/site-packages/wandb/sdk/wandb_run.py", line 449, in wrapper
    return func(self, *args, **kwargs)
  File "/home/users/yz705/.local/lib/python3.10/site-packages/wandb/sdk/wandb_run.py", line 390, in wrapper
    return func(self, *args, **kwargs)
  File "/home/users/yz705/.local/lib/python3.10/site-packages/wandb/sdk/wandb_run.py", line 2094, in finish
    return self._finish(exit_code, quiet)
  File "/home/users/yz705/.local/lib/python3.10/site-packages/wandb/sdk/wandb_run.py", line 2101, in _finish
    with telemetry.context(run=self) as tel:
  File "/home/users/yz705/.local/lib/python3.10/site-packages/wandb/sdk/lib/telemetry.py", line 42, in __exit__
    self._run._telemetry_callback(self._obj)
  File "/home/users/yz705/.local/lib/python3.10/site-packages/wandb/sdk/wandb_run.py", line 792, in _telemetry_callback
    self._telemetry_flush()
  File "/home/users/yz705/.local/lib/python3.10/site-packages/wandb/sdk/wandb_run.py", line 803, in _telemetry_flush
    self._backend.interface._publish_telemetry(self._telemetry_obj)
  File "/home/users/yz705/.local/lib/python3.10/site-packages/wandb/sdk/interface/interface_shared.py", line 101, in _publish_telemetry
    self._publish(rec)
  File "/home/users/yz705/.local/lib/python3.10/site-packages/wandb/sdk/interface/interface_sock.py", line 51, in _publish
    self._sock_client.send_record_publish(record)
  File "/home/users/yz705/.local/lib/python3.10/site-packages/wandb/sdk/lib/sock_client.py", line 221, in send_record_publish
    self.send_server_request(server_req)
  File "/home/users/yz705/.local/lib/python3.10/site-packages/wandb/sdk/lib/sock_client.py", line 155, in send_server_request
    self._send_message(msg)
  File "/home/users/yz705/.local/lib/python3.10/site-packages/wandb/sdk/lib/sock_client.py", line 152, in _send_message
    self._sendall_with_error_handle(header + data)
  File "/home/users/yz705/.local/lib/python3.10/site-packages/wandb/sdk/lib/sock_client.py", line 130, in _sendall_with_error_handle
    sent = self._sock.send(data)
BrokenPipeError: [Errno 32] Broken pipe
wandb: Agent Starting Run: aiwg26ko with config:
wandb: 	epochs: 160
wandb: 	lr: 1.0820812940197757
wandb: 	new_adj_dim: 12
wandb: 	numSampledCCs: 14
wandb: 	numSampledCycles: 52
wandb: 	pretrain_epochs: 60
Exception in thread Thread-5 (_run_job):
Traceback (most recent call last):
  File "/home/users/yz705/.local/lib/python3.10/site-packages/wandb/agents/pyagent.py", line 307, in _run_job
    self._function()
  File "/usr/project/xtmp/yz705/deep-topological-clustering/./graph_autoencoder.py", line 409, in one_tune_instance
    pretrain_labels_pred, train_labels_pred = train((train_loader, adj_matrices, labels_true))
TypeError: train() missing 1 required positional argument: 'dataset'

During handling of the above exception, another exception occurred:

Traceback (most recent call last):
  File "/usr/lib/python3.10/threading.py", line 1016, in _bootstrap_inner
    self.run()
  File "/usr/lib/python3.10/threading.py", line 953, in run
    self._target(*self._args, **self._kwargs)
  File "/home/users/yz705/.local/lib/python3.10/site-packages/wandb/agents/pyagent.py", line 312, in _run_job
    wandb.finish(exit_code=1)
  File "/home/users/yz705/.local/lib/python3.10/site-packages/wandb/sdk/wandb_run.py", line 4247, in finish
    wandb.run.finish(exit_code=exit_code, quiet=quiet)
  File "/home/users/yz705/.local/lib/python3.10/site-packages/wandb/sdk/wandb_run.py", line 449, in wrapper
    return func(self, *args, **kwargs)
  File "/home/users/yz705/.local/lib/python3.10/site-packages/wandb/sdk/wandb_run.py", line 390, in wrapper
    return func(self, *args, **kwargs)
  File "/home/users/yz705/.local/lib/python3.10/site-packages/wandb/sdk/wandb_run.py", line 2094, in finish
    return self._finish(exit_code, quiet)
  File "/home/users/yz705/.local/lib/python3.10/site-packages/wandb/sdk/wandb_run.py", line 2101, in _finish
    with telemetry.context(run=self) as tel:
  File "/home/users/yz705/.local/lib/python3.10/site-packages/wandb/sdk/lib/telemetry.py", line 42, in __exit__
    self._run._telemetry_callback(self._obj)
  File "/home/users/yz705/.local/lib/python3.10/site-packages/wandb/sdk/wandb_run.py", line 792, in _telemetry_callback
    self._telemetry_flush()
  File "/home/users/yz705/.local/lib/python3.10/site-packages/wandb/sdk/wandb_run.py", line 803, in _telemetry_flush
    self._backend.interface._publish_telemetry(self._telemetry_obj)
  File "/home/users/yz705/.local/lib/python3.10/site-packages/wandb/sdk/interface/interface_shared.py", line 101, in _publish_telemetry
    self._publish(rec)
  File "/home/users/yz705/.local/lib/python3.10/site-packages/wandb/sdk/interface/interface_sock.py", line 51, in _publish
    self._sock_client.send_record_publish(record)
  File "/home/users/yz705/.local/lib/python3.10/site-packages/wandb/sdk/lib/sock_client.py", line 221, in send_record_publish
    self.send_server_request(server_req)
  File "/home/users/yz705/.local/lib/python3.10/site-packages/wandb/sdk/lib/sock_client.py", line 155, in send_server_request
    self._send_message(msg)
  File "/home/users/yz705/.local/lib/python3.10/site-packages/wandb/sdk/lib/sock_client.py", line 152, in _send_message
    self._sendall_with_error_handle(header + data)
  File "/home/users/yz705/.local/lib/python3.10/site-packages/wandb/sdk/lib/sock_client.py", line 130, in _sendall_with_error_handle
    sent = self._sock.send(data)
BrokenPipeError: [Errno 32] Broken pipe
wandb: Sweep Agent: Waiting for job.
wandb: Job received.
wandb: Agent Starting Run: xs60oznk with config:
wandb: 	epochs: 60
wandb: 	lr: 1.09637877066829
wandb: 	new_adj_dim: 10
wandb: 	numSampledCCs: 16
wandb: 	numSampledCycles: 39
wandb: 	pretrain_epochs: 50
Exception in thread Thread-6 (_run_job):
Traceback (most recent call last):
  File "/home/users/yz705/.local/lib/python3.10/site-packages/wandb/agents/pyagent.py", line 307, in _run_job
    self._function()
  File "/usr/project/xtmp/yz705/deep-topological-clustering/./graph_autoencoder.py", line 409, in one_tune_instance
    pretrain_labels_pred, train_labels_pred = train((train_loader, adj_matrices, labels_true))
TypeError: train() missing 1 required positional argument: 'dataset'

During handling of the above exception, another exception occurred:

Traceback (most recent call last):
  File "/usr/lib/python3.10/threading.py", line 1016, in _bootstrap_inner
    self.run()
  File "/usr/lib/python3.10/threading.py", line 953, in run
    self._target(*self._args, **self._kwargs)
  File "/home/users/yz705/.local/lib/python3.10/site-packages/wandb/agents/pyagent.py", line 312, in _run_job
    wandb.finish(exit_code=1)
  File "/home/users/yz705/.local/lib/python3.10/site-packages/wandb/sdk/wandb_run.py", line 4247, in finish
    wandb.run.finish(exit_code=exit_code, quiet=quiet)
  File "/home/users/yz705/.local/lib/python3.10/site-packages/wandb/sdk/wandb_run.py", line 449, in wrapper
    return func(self, *args, **kwargs)
  File "/home/users/yz705/.local/lib/python3.10/site-packages/wandb/sdk/wandb_run.py", line 390, in wrapper
    return func(self, *args, **kwargs)
  File "/home/users/yz705/.local/lib/python3.10/site-packages/wandb/sdk/wandb_run.py", line 2094, in finish
    return self._finish(exit_code, quiet)
  File "/home/users/yz705/.local/lib/python3.10/site-packages/wandb/sdk/wandb_run.py", line 2101, in _finish
    with telemetry.context(run=self) as tel:
  File "/home/users/yz705/.local/lib/python3.10/site-packages/wandb/sdk/lib/telemetry.py", line 42, in __exit__
    self._run._telemetry_callback(self._obj)
  File "/home/users/yz705/.local/lib/python3.10/site-packages/wandb/sdk/wandb_run.py", line 792, in _telemetry_callback
    self._telemetry_flush()
  File "/home/users/yz705/.local/lib/python3.10/site-packages/wandb/sdk/wandb_run.py", line 803, in _telemetry_flush
    self._backend.interface._publish_telemetry(self._telemetry_obj)
  File "/home/users/yz705/.local/lib/python3.10/site-packages/wandb/sdk/interface/interface_shared.py", line 101, in _publish_telemetry
    self._publish(rec)
  File "/home/users/yz705/.local/lib/python3.10/site-packages/wandb/sdk/interface/interface_sock.py", line 51, in _publish
    self._sock_client.send_record_publish(record)
  File "/home/users/yz705/.local/lib/python3.10/site-packages/wandb/sdk/lib/sock_client.py", line 221, in send_record_publish
    self.send_server_request(server_req)
  File "/home/users/yz705/.local/lib/python3.10/site-packages/wandb/sdk/lib/sock_client.py", line 155, in send_server_request
    self._send_message(msg)
  File "/home/users/yz705/.local/lib/python3.10/site-packages/wandb/sdk/lib/sock_client.py", line 152, in _send_message
    self._sendall_with_error_handle(header + data)
  File "/home/users/yz705/.local/lib/python3.10/site-packages/wandb/sdk/lib/sock_client.py", line 130, in _sendall_with_error_handle
    sent = self._sock.send(data)
BrokenPipeError: [Errno 32] Broken pipe
wandb: Agent Starting Run: 6po6vdt3 with config:
wandb: 	epochs: 50
wandb: 	lr: 1.072520402932632
wandb: 	new_adj_dim: 14
wandb: 	numSampledCCs: 5
wandb: 	numSampledCycles: 30
wandb: 	pretrain_epochs: 40
Exception in thread Thread-7 (_run_job):
Traceback (most recent call last):
  File "/home/users/yz705/.local/lib/python3.10/site-packages/wandb/agents/pyagent.py", line 307, in _run_job
    self._function()
  File "/usr/project/xtmp/yz705/deep-topological-clustering/./graph_autoencoder.py", line 409, in one_tune_instance
    pretrain_labels_pred, train_labels_pred = train((train_loader, adj_matrices, labels_true))
TypeError: train() missing 1 required positional argument: 'dataset'

During handling of the above exception, another exception occurred:

Traceback (most recent call last):
  File "/usr/lib/python3.10/threading.py", line 1016, in _bootstrap_inner
    self.run()
  File "/usr/lib/python3.10/threading.py", line 953, in run
    self._target(*self._args, **self._kwargs)
  File "/home/users/yz705/.local/lib/python3.10/site-packages/wandb/agents/pyagent.py", line 312, in _run_job
    wandb.finish(exit_code=1)
  File "/home/users/yz705/.local/lib/python3.10/site-packages/wandb/sdk/wandb_run.py", line 4247, in finish
    wandb.run.finish(exit_code=exit_code, quiet=quiet)
  File "/home/users/yz705/.local/lib/python3.10/site-packages/wandb/sdk/wandb_run.py", line 449, in wrapper
    return func(self, *args, **kwargs)
  File "/home/users/yz705/.local/lib/python3.10/site-packages/wandb/sdk/wandb_run.py", line 390, in wrapper
    return func(self, *args, **kwargs)
  File "/home/users/yz705/.local/lib/python3.10/site-packages/wandb/sdk/wandb_run.py", line 2094, in finish
    return self._finish(exit_code, quiet)
  File "/home/users/yz705/.local/lib/python3.10/site-packages/wandb/sdk/wandb_run.py", line 2101, in _finish
    with telemetry.context(run=self) as tel:
  File "/home/users/yz705/.local/lib/python3.10/site-packages/wandb/sdk/lib/telemetry.py", line 42, in __exit__
    self._run._telemetry_callback(self._obj)
  File "/home/users/yz705/.local/lib/python3.10/site-packages/wandb/sdk/wandb_run.py", line 792, in _telemetry_callback
    self._telemetry_flush()
  File "/home/users/yz705/.local/lib/python3.10/site-packages/wandb/sdk/wandb_run.py", line 803, in _telemetry_flush
    self._backend.interface._publish_telemetry(self._telemetry_obj)
  File "/home/users/yz705/.local/lib/python3.10/site-packages/wandb/sdk/interface/interface_shared.py", line 101, in _publish_telemetry
    self._publish(rec)
  File "/home/users/yz705/.local/lib/python3.10/site-packages/wandb/sdk/interface/interface_sock.py", line 51, in _publish
    self._sock_client.send_record_publish(record)
  File "/home/users/yz705/.local/lib/python3.10/site-packages/wandb/sdk/lib/sock_client.py", line 221, in send_record_publish
    self.send_server_request(server_req)
  File "/home/users/yz705/.local/lib/python3.10/site-packages/wandb/sdk/lib/sock_client.py", line 155, in send_server_request
    self._send_message(msg)
  File "/home/users/yz705/.local/lib/python3.10/site-packages/wandb/sdk/lib/sock_client.py", line 152, in _send_message
    self._sendall_with_error_handle(header + data)
  File "/home/users/yz705/.local/lib/python3.10/site-packages/wandb/sdk/lib/sock_client.py", line 130, in _sendall_with_error_handle
    sent = self._sock.send(data)
BrokenPipeError: [Errno 32] Broken pipe
wandb: Sweep Agent: Waiting for job.
wandb: Job received.
wandb: Agent Starting Run: 9e40stif with config:
wandb: 	epochs: 110
wandb: 	lr: 1.0417196273995624
wandb: 	new_adj_dim: 13
wandb: 	numSampledCCs: 17
wandb: 	numSampledCycles: 31
wandb: 	pretrain_epochs: 90
Exception in thread Thread-8 (_run_job):
Traceback (most recent call last):
  File "/home/users/yz705/.local/lib/python3.10/site-packages/wandb/agents/pyagent.py", line 307, in _run_job
    self._function()
  File "/usr/project/xtmp/yz705/deep-topological-clustering/./graph_autoencoder.py", line 409, in one_tune_instance
    pretrain_labels_pred, train_labels_pred = train((train_loader, adj_matrices, labels_true))
TypeError: train() missing 1 required positional argument: 'dataset'

During handling of the above exception, another exception occurred:

Traceback (most recent call last):
  File "/usr/lib/python3.10/threading.py", line 1016, in _bootstrap_inner
    self.run()
  File "/usr/lib/python3.10/threading.py", line 953, in run
    self._target(*self._args, **self._kwargs)
  File "/home/users/yz705/.local/lib/python3.10/site-packages/wandb/agents/pyagent.py", line 312, in _run_job
    wandb.finish(exit_code=1)
  File "/home/users/yz705/.local/lib/python3.10/site-packages/wandb/sdk/wandb_run.py", line 4247, in finish
    wandb.run.finish(exit_code=exit_code, quiet=quiet)
  File "/home/users/yz705/.local/lib/python3.10/site-packages/wandb/sdk/wandb_run.py", line 449, in wrapper
    return func(self, *args, **kwargs)
  File "/home/users/yz705/.local/lib/python3.10/site-packages/wandb/sdk/wandb_run.py", line 390, in wrapper
    return func(self, *args, **kwargs)
  File "/home/users/yz705/.local/lib/python3.10/site-packages/wandb/sdk/wandb_run.py", line 2094, in finish
    return self._finish(exit_code, quiet)
  File "/home/users/yz705/.local/lib/python3.10/site-packages/wandb/sdk/wandb_run.py", line 2101, in _finish
    with telemetry.context(run=self) as tel:
  File "/home/users/yz705/.local/lib/python3.10/site-packages/wandb/sdk/lib/telemetry.py", line 42, in __exit__
    self._run._telemetry_callback(self._obj)
  File "/home/users/yz705/.local/lib/python3.10/site-packages/wandb/sdk/wandb_run.py", line 792, in _telemetry_callback
    self._telemetry_flush()
  File "/home/users/yz705/.local/lib/python3.10/site-packages/wandb/sdk/wandb_run.py", line 803, in _telemetry_flush
    self._backend.interface._publish_telemetry(self._telemetry_obj)
  File "/home/users/yz705/.local/lib/python3.10/site-packages/wandb/sdk/interface/interface_shared.py", line 101, in _publish_telemetry
    self._publish(rec)
  File "/home/users/yz705/.local/lib/python3.10/site-packages/wandb/sdk/interface/interface_sock.py", line 51, in _publish
    self._sock_client.send_record_publish(record)
  File "/home/users/yz705/.local/lib/python3.10/site-packages/wandb/sdk/lib/sock_client.py", line 221, in send_record_publish
    self.send_server_request(server_req)
  File "/home/users/yz705/.local/lib/python3.10/site-packages/wandb/sdk/lib/sock_client.py", line 155, in send_server_request
    self._send_message(msg)
  File "/home/users/yz705/.local/lib/python3.10/site-packages/wandb/sdk/lib/sock_client.py", line 152, in _send_message
    self._sendall_with_error_handle(header + data)
  File "/home/users/yz705/.local/lib/python3.10/site-packages/wandb/sdk/lib/sock_client.py", line 130, in _sendall_with_error_handle
    sent = self._sock.send(data)
BrokenPipeError: [Errno 32] Broken pipe
wandb: Agent Starting Run: wx2dvikh with config:
wandb: 	epochs: 80
wandb: 	lr: 1.0612042528791366
wandb: 	new_adj_dim: 10
wandb: 	numSampledCCs: 6
wandb: 	numSampledCycles: 58
wandb: 	pretrain_epochs: 60
Exception in thread Thread-9 (_run_job):
Traceback (most recent call last):
  File "/home/users/yz705/.local/lib/python3.10/site-packages/wandb/agents/pyagent.py", line 307, in _run_job
    self._function()
  File "/usr/project/xtmp/yz705/deep-topological-clustering/./graph_autoencoder.py", line 409, in one_tune_instance
    pretrain_labels_pred, train_labels_pred = train((train_loader, adj_matrices, labels_true))
TypeError: train() missing 1 required positional argument: 'dataset'

During handling of the above exception, another exception occurred:

Traceback (most recent call last):
  File "/usr/lib/python3.10/threading.py", line 1016, in _bootstrap_inner
    self.run()
  File "/usr/lib/python3.10/threading.py", line 953, in run
    self._target(*self._args, **self._kwargs)
  File "/home/users/yz705/.local/lib/python3.10/site-packages/wandb/agents/pyagent.py", line 312, in _run_job
    wandb.finish(exit_code=1)
  File "/home/users/yz705/.local/lib/python3.10/site-packages/wandb/sdk/wandb_run.py", line 4247, in finish
    wandb.run.finish(exit_code=exit_code, quiet=quiet)
  File "/home/users/yz705/.local/lib/python3.10/site-packages/wandb/sdk/wandb_run.py", line 449, in wrapper
    return func(self, *args, **kwargs)
  File "/home/users/yz705/.local/lib/python3.10/site-packages/wandb/sdk/wandb_run.py", line 390, in wrapper
    return func(self, *args, **kwargs)
  File "/home/users/yz705/.local/lib/python3.10/site-packages/wandb/sdk/wandb_run.py", line 2094, in finish
    return self._finish(exit_code, quiet)
  File "/home/users/yz705/.local/lib/python3.10/site-packages/wandb/sdk/wandb_run.py", line 2101, in _finish
    with telemetry.context(run=self) as tel:
  File "/home/users/yz705/.local/lib/python3.10/site-packages/wandb/sdk/lib/telemetry.py", line 42, in __exit__
    self._run._telemetry_callback(self._obj)
  File "/home/users/yz705/.local/lib/python3.10/site-packages/wandb/sdk/wandb_run.py", line 792, in _telemetry_callback
    self._telemetry_flush()
  File "/home/users/yz705/.local/lib/python3.10/site-packages/wandb/sdk/wandb_run.py", line 803, in _telemetry_flush
    self._backend.interface._publish_telemetry(self._telemetry_obj)
  File "/home/users/yz705/.local/lib/python3.10/site-packages/wandb/sdk/interface/interface_shared.py", line 101, in _publish_telemetry
    self._publish(rec)
  File "/home/users/yz705/.local/lib/python3.10/site-packages/wandb/sdk/interface/interface_sock.py", line 51, in _publish
    self._sock_client.send_record_publish(record)
  File "/home/users/yz705/.local/lib/python3.10/site-packages/wandb/sdk/lib/sock_client.py", line 221, in send_record_publish
    self.send_server_request(server_req)
  File "/home/users/yz705/.local/lib/python3.10/site-packages/wandb/sdk/lib/sock_client.py", line 155, in send_server_request
    self._send_message(msg)
  File "/home/users/yz705/.local/lib/python3.10/site-packages/wandb/sdk/lib/sock_client.py", line 152, in _send_message
    self._sendall_with_error_handle(header + data)
  File "/home/users/yz705/.local/lib/python3.10/site-packages/wandb/sdk/lib/sock_client.py", line 130, in _sendall_with_error_handle
    sent = self._sock.send(data)
BrokenPipeError: [Errno 32] Broken pipe
wandb: Sweep Agent: Waiting for job.
wandb: Job received.
wandb: Agent Starting Run: doxiqs7b with config:
wandb: 	epochs: 130
wandb: 	lr: 1.0290938455871823
wandb: 	new_adj_dim: 13
wandb: 	numSampledCCs: 8
wandb: 	numSampledCycles: 8
wandb: 	pretrain_epochs: 60
Exception in thread Thread-10 (_run_job):
Traceback (most recent call last):
  File "/home/users/yz705/.local/lib/python3.10/site-packages/wandb/agents/pyagent.py", line 307, in _run_job
    self._function()
  File "/usr/project/xtmp/yz705/deep-topological-clustering/./graph_autoencoder.py", line 409, in one_tune_instance
    pretrain_labels_pred, train_labels_pred = train((train_loader, adj_matrices, labels_true))
TypeError: train() missing 1 required positional argument: 'dataset'

During handling of the above exception, another exception occurred:

Traceback (most recent call last):
  File "/usr/lib/python3.10/threading.py", line 1016, in _bootstrap_inner
    self.run()
  File "/usr/lib/python3.10/threading.py", line 953, in run
    self._target(*self._args, **self._kwargs)
  File "/home/users/yz705/.local/lib/python3.10/site-packages/wandb/agents/pyagent.py", line 312, in _run_job
    wandb.finish(exit_code=1)
  File "/home/users/yz705/.local/lib/python3.10/site-packages/wandb/sdk/wandb_run.py", line 4247, in finish
    wandb.run.finish(exit_code=exit_code, quiet=quiet)
  File "/home/users/yz705/.local/lib/python3.10/site-packages/wandb/sdk/wandb_run.py", line 449, in wrapper
    return func(self, *args, **kwargs)
  File "/home/users/yz705/.local/lib/python3.10/site-packages/wandb/sdk/wandb_run.py", line 390, in wrapper
    return func(self, *args, **kwargs)
  File "/home/users/yz705/.local/lib/python3.10/site-packages/wandb/sdk/wandb_run.py", line 2094, in finish
    return self._finish(exit_code, quiet)
  File "/home/users/yz705/.local/lib/python3.10/site-packages/wandb/sdk/wandb_run.py", line 2101, in _finish
    with telemetry.context(run=self) as tel:
  File "/home/users/yz705/.local/lib/python3.10/site-packages/wandb/sdk/lib/telemetry.py", line 42, in __exit__
    self._run._telemetry_callback(self._obj)
  File "/home/users/yz705/.local/lib/python3.10/site-packages/wandb/sdk/wandb_run.py", line 792, in _telemetry_callback
    self._telemetry_flush()
  File "/home/users/yz705/.local/lib/python3.10/site-packages/wandb/sdk/wandb_run.py", line 803, in _telemetry_flush
    self._backend.interface._publish_telemetry(self._telemetry_obj)
  File "/home/users/yz705/.local/lib/python3.10/site-packages/wandb/sdk/interface/interface_shared.py", line 101, in _publish_telemetry
    self._publish(rec)
  File "/home/users/yz705/.local/lib/python3.10/site-packages/wandb/sdk/interface/interface_sock.py", line 51, in _publish
    self._sock_client.send_record_publish(record)
  File "/home/users/yz705/.local/lib/python3.10/site-packages/wandb/sdk/lib/sock_client.py", line 221, in send_record_publish
    self.send_server_request(server_req)
  File "/home/users/yz705/.local/lib/python3.10/site-packages/wandb/sdk/lib/sock_client.py", line 155, in send_server_request
    self._send_message(msg)
  File "/home/users/yz705/.local/lib/python3.10/site-packages/wandb/sdk/lib/sock_client.py", line 152, in _send_message
    self._sendall_with_error_handle(header + data)
  File "/home/users/yz705/.local/lib/python3.10/site-packages/wandb/sdk/lib/sock_client.py", line 130, in _sendall_with_error_handle
    sent = self._sock.send(data)
BrokenPipeError: [Errno 32] Broken pipe
wandb: Sweep Agent: Waiting for job.
wandb: Job received.
wandb: Agent Starting Run: xu7eseh3 with config:
wandb: 	epochs: 100
wandb: 	lr: 1.0261950645627531
wandb: 	new_adj_dim: 13
wandb: 	numSampledCCs: 13
wandb: 	numSampledCycles: 17
wandb: 	pretrain_epochs: 50
Exception in thread Thread-11 (_run_job):
Traceback (most recent call last):
  File "/home/users/yz705/.local/lib/python3.10/site-packages/wandb/agents/pyagent.py", line 307, in _run_job
    self._function()
  File "/usr/project/xtmp/yz705/deep-topological-clustering/./graph_autoencoder.py", line 409, in one_tune_instance
    pretrain_labels_pred, train_labels_pred = train((train_loader, adj_matrices, labels_true))
TypeError: train() missing 1 required positional argument: 'dataset'

During handling of the above exception, another exception occurred:

Traceback (most recent call last):
  File "/usr/lib/python3.10/threading.py", line 1016, in _bootstrap_inner
    self.run()
  File "/usr/lib/python3.10/threading.py", line 953, in run
    self._target(*self._args, **self._kwargs)
  File "/home/users/yz705/.local/lib/python3.10/site-packages/wandb/agents/pyagent.py", line 312, in _run_job
    wandb.finish(exit_code=1)
  File "/home/users/yz705/.local/lib/python3.10/site-packages/wandb/sdk/wandb_run.py", line 4247, in finish
    wandb.run.finish(exit_code=exit_code, quiet=quiet)
  File "/home/users/yz705/.local/lib/python3.10/site-packages/wandb/sdk/wandb_run.py", line 449, in wrapper
    return func(self, *args, **kwargs)
  File "/home/users/yz705/.local/lib/python3.10/site-packages/wandb/sdk/wandb_run.py", line 390, in wrapper
    return func(self, *args, **kwargs)
  File "/home/users/yz705/.local/lib/python3.10/site-packages/wandb/sdk/wandb_run.py", line 2094, in finish
    return self._finish(exit_code, quiet)
  File "/home/users/yz705/.local/lib/python3.10/site-packages/wandb/sdk/wandb_run.py", line 2101, in _finish
    with telemetry.context(run=self) as tel:
  File "/home/users/yz705/.local/lib/python3.10/site-packages/wandb/sdk/lib/telemetry.py", line 42, in __exit__
    self._run._telemetry_callback(self._obj)
  File "/home/users/yz705/.local/lib/python3.10/site-packages/wandb/sdk/wandb_run.py", line 792, in _telemetry_callback
    self._telemetry_flush()
  File "/home/users/yz705/.local/lib/python3.10/site-packages/wandb/sdk/wandb_run.py", line 803, in _telemetry_flush
    self._backend.interface._publish_telemetry(self._telemetry_obj)
  File "/home/users/yz705/.local/lib/python3.10/site-packages/wandb/sdk/interface/interface_shared.py", line 101, in _publish_telemetry
    self._publish(rec)
  File "/home/users/yz705/.local/lib/python3.10/site-packages/wandb/sdk/interface/interface_sock.py", line 51, in _publish
    self._sock_client.send_record_publish(record)
  File "/home/users/yz705/.local/lib/python3.10/site-packages/wandb/sdk/lib/sock_client.py", line 221, in send_record_publish
    self.send_server_request(server_req)
  File "/home/users/yz705/.local/lib/python3.10/site-packages/wandb/sdk/lib/sock_client.py", line 155, in send_server_request
    self._send_message(msg)
  File "/home/users/yz705/.local/lib/python3.10/site-packages/wandb/sdk/lib/sock_client.py", line 152, in _send_message
    self._sendall_with_error_handle(header + data)
  File "/home/users/yz705/.local/lib/python3.10/site-packages/wandb/sdk/lib/sock_client.py", line 130, in _sendall_with_error_handle
    sent = self._sock.send(data)
BrokenPipeError: [Errno 32] Broken pipe
wandb: Agent Starting Run: lf82hgk0 with config:
wandb: 	epochs: 130
wandb: 	lr: 1.0716097729806633
wandb: 	new_adj_dim: 12
wandb: 	numSampledCCs: 13
wandb: 	numSampledCycles: 8
wandb: 	pretrain_epochs: 50
Exception in thread Thread-12 (_run_job):
Traceback (most recent call last):
  File "/home/users/yz705/.local/lib/python3.10/site-packages/wandb/agents/pyagent.py", line 307, in _run_job
    self._function()
  File "/usr/project/xtmp/yz705/deep-topological-clustering/./graph_autoencoder.py", line 409, in one_tune_instance
    pretrain_labels_pred, train_labels_pred = train((train_loader, adj_matrices, labels_true))
TypeError: train() missing 1 required positional argument: 'dataset'

During handling of the above exception, another exception occurred:

Traceback (most recent call last):
  File "/usr/lib/python3.10/threading.py", line 1016, in _bootstrap_inner
    self.run()
  File "/usr/lib/python3.10/threading.py", line 953, in run
    self._target(*self._args, **self._kwargs)
  File "/home/users/yz705/.local/lib/python3.10/site-packages/wandb/agents/pyagent.py", line 312, in _run_job
    wandb.finish(exit_code=1)
  File "/home/users/yz705/.local/lib/python3.10/site-packages/wandb/sdk/wandb_run.py", line 4247, in finish
    wandb.run.finish(exit_code=exit_code, quiet=quiet)
  File "/home/users/yz705/.local/lib/python3.10/site-packages/wandb/sdk/wandb_run.py", line 449, in wrapper
    return func(self, *args, **kwargs)
  File "/home/users/yz705/.local/lib/python3.10/site-packages/wandb/sdk/wandb_run.py", line 390, in wrapper
    return func(self, *args, **kwargs)
  File "/home/users/yz705/.local/lib/python3.10/site-packages/wandb/sdk/wandb_run.py", line 2094, in finish
    return self._finish(exit_code, quiet)
  File "/home/users/yz705/.local/lib/python3.10/site-packages/wandb/sdk/wandb_run.py", line 2101, in _finish
    with telemetry.context(run=self) as tel:
  File "/home/users/yz705/.local/lib/python3.10/site-packages/wandb/sdk/lib/telemetry.py", line 42, in __exit__
    self._run._telemetry_callback(self._obj)
  File "/home/users/yz705/.local/lib/python3.10/site-packages/wandb/sdk/wandb_run.py", line 792, in _telemetry_callback
    self._telemetry_flush()
  File "/home/users/yz705/.local/lib/python3.10/site-packages/wandb/sdk/wandb_run.py", line 803, in _telemetry_flush
    self._backend.interface._publish_telemetry(self._telemetry_obj)
  File "/home/users/yz705/.local/lib/python3.10/site-packages/wandb/sdk/interface/interface_shared.py", line 101, in _publish_telemetry
    self._publish(rec)
  File "/home/users/yz705/.local/lib/python3.10/site-packages/wandb/sdk/interface/interface_sock.py", line 51, in _publish
    self._sock_client.send_record_publish(record)
  File "/home/users/yz705/.local/lib/python3.10/site-packages/wandb/sdk/lib/sock_client.py", line 221, in send_record_publish
    self.send_server_request(server_req)
  File "/home/users/yz705/.local/lib/python3.10/site-packages/wandb/sdk/lib/sock_client.py", line 155, in send_server_request
    self._send_message(msg)
  File "/home/users/yz705/.local/lib/python3.10/site-packages/wandb/sdk/lib/sock_client.py", line 152, in _send_message
    self._sendall_with_error_handle(header + data)
  File "/home/users/yz705/.local/lib/python3.10/site-packages/wandb/sdk/lib/sock_client.py", line 130, in _sendall_with_error_handle
    sent = self._sock.send(data)
BrokenPipeError: [Errno 32] Broken pipe
wandb: Sweep Agent: Waiting for job.
wandb: Job received.
wandb: Agent Starting Run: 8mqiqrol with config:
wandb: 	epochs: 190
wandb: 	lr: 1.0860890565195245
wandb: 	new_adj_dim: 9
wandb: 	numSampledCCs: 14
wandb: 	numSampledCycles: 33
wandb: 	pretrain_epochs: 80
Exception in thread Thread-13 (_run_job):
Traceback (most recent call last):
  File "/home/users/yz705/.local/lib/python3.10/site-packages/wandb/agents/pyagent.py", line 307, in _run_job
    self._function()
  File "/usr/project/xtmp/yz705/deep-topological-clustering/./graph_autoencoder.py", line 409, in one_tune_instance
    pretrain_labels_pred, train_labels_pred = train((train_loader, adj_matrices, labels_true))
TypeError: train() missing 1 required positional argument: 'dataset'

During handling of the above exception, another exception occurred:

Traceback (most recent call last):
  File "/usr/lib/python3.10/threading.py", line 1016, in _bootstrap_inner
    self.run()
  File "/usr/lib/python3.10/threading.py", line 953, in run
    self._target(*self._args, **self._kwargs)
  File "/home/users/yz705/.local/lib/python3.10/site-packages/wandb/agents/pyagent.py", line 312, in _run_job
    wandb.finish(exit_code=1)
  File "/home/users/yz705/.local/lib/python3.10/site-packages/wandb/sdk/wandb_run.py", line 4247, in finish
    wandb.run.finish(exit_code=exit_code, quiet=quiet)
  File "/home/users/yz705/.local/lib/python3.10/site-packages/wandb/sdk/wandb_run.py", line 449, in wrapper
    return func(self, *args, **kwargs)
  File "/home/users/yz705/.local/lib/python3.10/site-packages/wandb/sdk/wandb_run.py", line 390, in wrapper
    return func(self, *args, **kwargs)
  File "/home/users/yz705/.local/lib/python3.10/site-packages/wandb/sdk/wandb_run.py", line 2094, in finish
    return self._finish(exit_code, quiet)
  File "/home/users/yz705/.local/lib/python3.10/site-packages/wandb/sdk/wandb_run.py", line 2101, in _finish
    with telemetry.context(run=self) as tel:
  File "/home/users/yz705/.local/lib/python3.10/site-packages/wandb/sdk/lib/telemetry.py", line 42, in __exit__
    self._run._telemetry_callback(self._obj)
  File "/home/users/yz705/.local/lib/python3.10/site-packages/wandb/sdk/wandb_run.py", line 792, in _telemetry_callback
    self._telemetry_flush()
  File "/home/users/yz705/.local/lib/python3.10/site-packages/wandb/sdk/wandb_run.py", line 803, in _telemetry_flush
    self._backend.interface._publish_telemetry(self._telemetry_obj)
  File "/home/users/yz705/.local/lib/python3.10/site-packages/wandb/sdk/interface/interface_shared.py", line 101, in _publish_telemetry
    self._publish(rec)
  File "/home/users/yz705/.local/lib/python3.10/site-packages/wandb/sdk/interface/interface_sock.py", line 51, in _publish
    self._sock_client.send_record_publish(record)
  File "/home/users/yz705/.local/lib/python3.10/site-packages/wandb/sdk/lib/sock_client.py", line 221, in send_record_publish
    self.send_server_request(server_req)
  File "/home/users/yz705/.local/lib/python3.10/site-packages/wandb/sdk/lib/sock_client.py", line 155, in send_server_request
    self._send_message(msg)
  File "/home/users/yz705/.local/lib/python3.10/site-packages/wandb/sdk/lib/sock_client.py", line 152, in _send_message
    self._sendall_with_error_handle(header + data)
  File "/home/users/yz705/.local/lib/python3.10/site-packages/wandb/sdk/lib/sock_client.py", line 130, in _sendall_with_error_handle
    sent = self._sock.send(data)
BrokenPipeError: [Errno 32] Broken pipe
wandb: Sweep Agent: Waiting for job.
wandb: Job received.
wandb: Agent Starting Run: yqc6lwqd with config:
wandb: 	epochs: 70
wandb: 	lr: 1.0125852483490825
wandb: 	new_adj_dim: 6
wandb: 	numSampledCCs: 8
wandb: 	numSampledCycles: 40
wandb: 	pretrain_epochs: 60
Exception in thread Thread-14 (_run_job):
Traceback (most recent call last):
  File "/home/users/yz705/.local/lib/python3.10/site-packages/wandb/agents/pyagent.py", line 307, in _run_job
    self._function()
  File "/usr/project/xtmp/yz705/deep-topological-clustering/./graph_autoencoder.py", line 409, in one_tune_instance
    pretrain_labels_pred, train_labels_pred = train((train_loader, adj_matrices, labels_true))
TypeError: train() missing 1 required positional argument: 'dataset'

During handling of the above exception, another exception occurred:

Traceback (most recent call last):
  File "/usr/lib/python3.10/threading.py", line 1016, in _bootstrap_inner
    self.run()
  File "/usr/lib/python3.10/threading.py", line 953, in run
    self._target(*self._args, **self._kwargs)
  File "/home/users/yz705/.local/lib/python3.10/site-packages/wandb/agents/pyagent.py", line 312, in _run_job
    wandb.finish(exit_code=1)
  File "/home/users/yz705/.local/lib/python3.10/site-packages/wandb/sdk/wandb_run.py", line 4247, in finish
    wandb.run.finish(exit_code=exit_code, quiet=quiet)
  File "/home/users/yz705/.local/lib/python3.10/site-packages/wandb/sdk/wandb_run.py", line 449, in wrapper
    return func(self, *args, **kwargs)
  File "/home/users/yz705/.local/lib/python3.10/site-packages/wandb/sdk/wandb_run.py", line 390, in wrapper
    return func(self, *args, **kwargs)
  File "/home/users/yz705/.local/lib/python3.10/site-packages/wandb/sdk/wandb_run.py", line 2094, in finish
    return self._finish(exit_code, quiet)
  File "/home/users/yz705/.local/lib/python3.10/site-packages/wandb/sdk/wandb_run.py", line 2101, in _finish
    with telemetry.context(run=self) as tel:
  File "/home/users/yz705/.local/lib/python3.10/site-packages/wandb/sdk/lib/telemetry.py", line 42, in __exit__
    self._run._telemetry_callback(self._obj)
  File "/home/users/yz705/.local/lib/python3.10/site-packages/wandb/sdk/wandb_run.py", line 792, in _telemetry_callback
    self._telemetry_flush()
  File "/home/users/yz705/.local/lib/python3.10/site-packages/wandb/sdk/wandb_run.py", line 803, in _telemetry_flush
    self._backend.interface._publish_telemetry(self._telemetry_obj)
  File "/home/users/yz705/.local/lib/python3.10/site-packages/wandb/sdk/interface/interface_shared.py", line 101, in _publish_telemetry
    self._publish(rec)
  File "/home/users/yz705/.local/lib/python3.10/site-packages/wandb/sdk/interface/interface_sock.py", line 51, in _publish
    self._sock_client.send_record_publish(record)
  File "/home/users/yz705/.local/lib/python3.10/site-packages/wandb/sdk/lib/sock_client.py", line 221, in send_record_publish
    self.send_server_request(server_req)
  File "/home/users/yz705/.local/lib/python3.10/site-packages/wandb/sdk/lib/sock_client.py", line 155, in send_server_request
    self._send_message(msg)
  File "/home/users/yz705/.local/lib/python3.10/site-packages/wandb/sdk/lib/sock_client.py", line 152, in _send_message
    self._sendall_with_error_handle(header + data)
  File "/home/users/yz705/.local/lib/python3.10/site-packages/wandb/sdk/lib/sock_client.py", line 130, in _sendall_with_error_handle
    sent = self._sock.send(data)
BrokenPipeError: [Errno 32] Broken pipe
wandb: Agent Starting Run: ds0jr59s with config:
wandb: 	epochs: 50
wandb: 	lr: 1.0324987554088485
wandb: 	new_adj_dim: 9
wandb: 	numSampledCCs: 13
wandb: 	numSampledCycles: 52
wandb: 	pretrain_epochs: 70
Exception in thread Thread-15 (_run_job):
Traceback (most recent call last):
  File "/home/users/yz705/.local/lib/python3.10/site-packages/wandb/agents/pyagent.py", line 307, in _run_job
    self._function()
  File "/usr/project/xtmp/yz705/deep-topological-clustering/./graph_autoencoder.py", line 409, in one_tune_instance
    pretrain_labels_pred, train_labels_pred = train((train_loader, adj_matrices, labels_true))
TypeError: train() missing 1 required positional argument: 'dataset'

During handling of the above exception, another exception occurred:

Traceback (most recent call last):
  File "/usr/lib/python3.10/threading.py", line 1016, in _bootstrap_inner
    self.run()
  File "/usr/lib/python3.10/threading.py", line 953, in run
    self._target(*self._args, **self._kwargs)
  File "/home/users/yz705/.local/lib/python3.10/site-packages/wandb/agents/pyagent.py", line 312, in _run_job
    wandb.finish(exit_code=1)
  File "/home/users/yz705/.local/lib/python3.10/site-packages/wandb/sdk/wandb_run.py", line 4247, in finish
    wandb.run.finish(exit_code=exit_code, quiet=quiet)
  File "/home/users/yz705/.local/lib/python3.10/site-packages/wandb/sdk/wandb_run.py", line 449, in wrapper
    return func(self, *args, **kwargs)
  File "/home/users/yz705/.local/lib/python3.10/site-packages/wandb/sdk/wandb_run.py", line 390, in wrapper
    return func(self, *args, **kwargs)
  File "/home/users/yz705/.local/lib/python3.10/site-packages/wandb/sdk/wandb_run.py", line 2094, in finish
    return self._finish(exit_code, quiet)
  File "/home/users/yz705/.local/lib/python3.10/site-packages/wandb/sdk/wandb_run.py", line 2101, in _finish
    with telemetry.context(run=self) as tel:
  File "/home/users/yz705/.local/lib/python3.10/site-packages/wandb/sdk/lib/telemetry.py", line 42, in __exit__
    self._run._telemetry_callback(self._obj)
  File "/home/users/yz705/.local/lib/python3.10/site-packages/wandb/sdk/wandb_run.py", line 792, in _telemetry_callback
    self._telemetry_flush()
  File "/home/users/yz705/.local/lib/python3.10/site-packages/wandb/sdk/wandb_run.py", line 803, in _telemetry_flush
    self._backend.interface._publish_telemetry(self._telemetry_obj)
  File "/home/users/yz705/.local/lib/python3.10/site-packages/wandb/sdk/interface/interface_shared.py", line 101, in _publish_telemetry
    self._publish(rec)
  File "/home/users/yz705/.local/lib/python3.10/site-packages/wandb/sdk/interface/interface_sock.py", line 51, in _publish
    self._sock_client.send_record_publish(record)
  File "/home/users/yz705/.local/lib/python3.10/site-packages/wandb/sdk/lib/sock_client.py", line 221, in send_record_publish
    self.send_server_request(server_req)
  File "/home/users/yz705/.local/lib/python3.10/site-packages/wandb/sdk/lib/sock_client.py", line 155, in send_server_request
    self._send_message(msg)
  File "/home/users/yz705/.local/lib/python3.10/site-packages/wandb/sdk/lib/sock_client.py", line 152, in _send_message
    self._sendall_with_error_handle(header + data)
  File "/home/users/yz705/.local/lib/python3.10/site-packages/wandb/sdk/lib/sock_client.py", line 130, in _sendall_with_error_handle
    sent = self._sock.send(data)
BrokenPipeError: [Errno 32] Broken pipe
wandb: Sweep Agent: Waiting for job.
wandb: Job received.
wandb: Agent Starting Run: of6jz8nq with config:
wandb: 	epochs: 120
wandb: 	lr: 1.0219297992748435
wandb: 	new_adj_dim: 8
wandb: 	numSampledCCs: 11
wandb: 	numSampledCycles: 6
wandb: 	pretrain_epochs: 30
Exception in thread Thread-16 (_run_job):
Traceback (most recent call last):
  File "/home/users/yz705/.local/lib/python3.10/site-packages/wandb/agents/pyagent.py", line 307, in _run_job
    self._function()
  File "/usr/project/xtmp/yz705/deep-topological-clustering/./graph_autoencoder.py", line 409, in one_tune_instance
    pretrain_labels_pred, train_labels_pred = train((train_loader, adj_matrices, labels_true))
TypeError: train() missing 1 required positional argument: 'dataset'

During handling of the above exception, another exception occurred:

Traceback (most recent call last):
  File "/usr/lib/python3.10/threading.py", line 1016, in _bootstrap_inner
    self.run()
  File "/usr/lib/python3.10/threading.py", line 953, in run
    self._target(*self._args, **self._kwargs)
  File "/home/users/yz705/.local/lib/python3.10/site-packages/wandb/agents/pyagent.py", line 312, in _run_job
    wandb.finish(exit_code=1)
  File "/home/users/yz705/.local/lib/python3.10/site-packages/wandb/sdk/wandb_run.py", line 4247, in finish
    wandb.run.finish(exit_code=exit_code, quiet=quiet)
  File "/home/users/yz705/.local/lib/python3.10/site-packages/wandb/sdk/wandb_run.py", line 449, in wrapper
    return func(self, *args, **kwargs)
  File "/home/users/yz705/.local/lib/python3.10/site-packages/wandb/sdk/wandb_run.py", line 390, in wrapper
    return func(self, *args, **kwargs)
  File "/home/users/yz705/.local/lib/python3.10/site-packages/wandb/sdk/wandb_run.py", line 2094, in finish
    return self._finish(exit_code, quiet)
  File "/home/users/yz705/.local/lib/python3.10/site-packages/wandb/sdk/wandb_run.py", line 2101, in _finish
    with telemetry.context(run=self) as tel:
  File "/home/users/yz705/.local/lib/python3.10/site-packages/wandb/sdk/lib/telemetry.py", line 42, in __exit__
    self._run._telemetry_callback(self._obj)
  File "/home/users/yz705/.local/lib/python3.10/site-packages/wandb/sdk/wandb_run.py", line 792, in _telemetry_callback
    self._telemetry_flush()
  File "/home/users/yz705/.local/lib/python3.10/site-packages/wandb/sdk/wandb_run.py", line 803, in _telemetry_flush
    self._backend.interface._publish_telemetry(self._telemetry_obj)
  File "/home/users/yz705/.local/lib/python3.10/site-packages/wandb/sdk/interface/interface_shared.py", line 101, in _publish_telemetry
    self._publish(rec)
  File "/home/users/yz705/.local/lib/python3.10/site-packages/wandb/sdk/interface/interface_sock.py", line 51, in _publish
    self._sock_client.send_record_publish(record)
  File "/home/users/yz705/.local/lib/python3.10/site-packages/wandb/sdk/lib/sock_client.py", line 221, in send_record_publish
    self.send_server_request(server_req)
  File "/home/users/yz705/.local/lib/python3.10/site-packages/wandb/sdk/lib/sock_client.py", line 155, in send_server_request
    self._send_message(msg)
  File "/home/users/yz705/.local/lib/python3.10/site-packages/wandb/sdk/lib/sock_client.py", line 152, in _send_message
    self._sendall_with_error_handle(header + data)
  File "/home/users/yz705/.local/lib/python3.10/site-packages/wandb/sdk/lib/sock_client.py", line 130, in _sendall_with_error_handle
    sent = self._sock.send(data)
BrokenPipeError: [Errno 32] Broken pipe
wandb: Agent Starting Run: 8pbxa7q5 with config:
wandb: 	epochs: 100
wandb: 	lr: 1.001834268431035
wandb: 	new_adj_dim: 8
wandb: 	numSampledCCs: 13
wandb: 	numSampledCycles: 56
wandb: 	pretrain_epochs: 70
Exception in thread Thread-17 (_run_job):
Traceback (most recent call last):
  File "/home/users/yz705/.local/lib/python3.10/site-packages/wandb/agents/pyagent.py", line 307, in _run_job
    self._function()
  File "/usr/project/xtmp/yz705/deep-topological-clustering/./graph_autoencoder.py", line 409, in one_tune_instance
    pretrain_labels_pred, train_labels_pred = train((train_loader, adj_matrices, labels_true))
TypeError: train() missing 1 required positional argument: 'dataset'

During handling of the above exception, another exception occurred:

Traceback (most recent call last):
  File "/usr/lib/python3.10/threading.py", line 1016, in _bootstrap_inner
    self.run()
  File "/usr/lib/python3.10/threading.py", line 953, in run
    self._target(*self._args, **self._kwargs)
  File "/home/users/yz705/.local/lib/python3.10/site-packages/wandb/agents/pyagent.py", line 312, in _run_job
    wandb.finish(exit_code=1)
  File "/home/users/yz705/.local/lib/python3.10/site-packages/wandb/sdk/wandb_run.py", line 4247, in finish
    wandb.run.finish(exit_code=exit_code, quiet=quiet)
  File "/home/users/yz705/.local/lib/python3.10/site-packages/wandb/sdk/wandb_run.py", line 449, in wrapper
    return func(self, *args, **kwargs)
  File "/home/users/yz705/.local/lib/python3.10/site-packages/wandb/sdk/wandb_run.py", line 390, in wrapper
    return func(self, *args, **kwargs)
  File "/home/users/yz705/.local/lib/python3.10/site-packages/wandb/sdk/wandb_run.py", line 2094, in finish
    return self._finish(exit_code, quiet)
  File "/home/users/yz705/.local/lib/python3.10/site-packages/wandb/sdk/wandb_run.py", line 2101, in _finish
    with telemetry.context(run=self) as tel:
  File "/home/users/yz705/.local/lib/python3.10/site-packages/wandb/sdk/lib/telemetry.py", line 42, in __exit__
    self._run._telemetry_callback(self._obj)
  File "/home/users/yz705/.local/lib/python3.10/site-packages/wandb/sdk/wandb_run.py", line 792, in _telemetry_callback
    self._telemetry_flush()
  File "/home/users/yz705/.local/lib/python3.10/site-packages/wandb/sdk/wandb_run.py", line 803, in _telemetry_flush
    self._backend.interface._publish_telemetry(self._telemetry_obj)
  File "/home/users/yz705/.local/lib/python3.10/site-packages/wandb/sdk/interface/interface_shared.py", line 101, in _publish_telemetry
    self._publish(rec)
  File "/home/users/yz705/.local/lib/python3.10/site-packages/wandb/sdk/interface/interface_sock.py", line 51, in _publish
    self._sock_client.send_record_publish(record)
  File "/home/users/yz705/.local/lib/python3.10/site-packages/wandb/sdk/lib/sock_client.py", line 221, in send_record_publish
    self.send_server_request(server_req)
  File "/home/users/yz705/.local/lib/python3.10/site-packages/wandb/sdk/lib/sock_client.py", line 155, in send_server_request
    self._send_message(msg)
  File "/home/users/yz705/.local/lib/python3.10/site-packages/wandb/sdk/lib/sock_client.py", line 152, in _send_message
    self._sendall_with_error_handle(header + data)
  File "/home/users/yz705/.local/lib/python3.10/site-packages/wandb/sdk/lib/sock_client.py", line 130, in _sendall_with_error_handle
    sent = self._sock.send(data)
BrokenPipeError: [Errno 32] Broken pipe
wandb: Sweep Agent: Waiting for job.
wandb: Job received.
wandb: Agent Starting Run: h07xv7fi with config:
wandb: 	epochs: 50
wandb: 	lr: 1.0371409758531795
wandb: 	new_adj_dim: 9
wandb: 	numSampledCCs: 7
wandb: 	numSampledCycles: 6
wandb: 	pretrain_epochs: 70
Exception in thread Thread-18 (_run_job):
Traceback (most recent call last):
  File "/home/users/yz705/.local/lib/python3.10/site-packages/wandb/agents/pyagent.py", line 307, in _run_job
    self._function()
  File "/usr/project/xtmp/yz705/deep-topological-clustering/./graph_autoencoder.py", line 409, in one_tune_instance
    pretrain_labels_pred, train_labels_pred = train((train_loader, adj_matrices, labels_true))
TypeError: train() missing 1 required positional argument: 'dataset'

During handling of the above exception, another exception occurred:

Traceback (most recent call last):
  File "/usr/lib/python3.10/threading.py", line 1016, in _bootstrap_inner
    self.run()
  File "/usr/lib/python3.10/threading.py", line 953, in run
    self._target(*self._args, **self._kwargs)
  File "/home/users/yz705/.local/lib/python3.10/site-packages/wandb/agents/pyagent.py", line 312, in _run_job
    wandb.finish(exit_code=1)
  File "/home/users/yz705/.local/lib/python3.10/site-packages/wandb/sdk/wandb_run.py", line 4247, in finish
    wandb.run.finish(exit_code=exit_code, quiet=quiet)
  File "/home/users/yz705/.local/lib/python3.10/site-packages/wandb/sdk/wandb_run.py", line 449, in wrapper
    return func(self, *args, **kwargs)
  File "/home/users/yz705/.local/lib/python3.10/site-packages/wandb/sdk/wandb_run.py", line 390, in wrapper
    return func(self, *args, **kwargs)
  File "/home/users/yz705/.local/lib/python3.10/site-packages/wandb/sdk/wandb_run.py", line 2094, in finish
    return self._finish(exit_code, quiet)
  File "/home/users/yz705/.local/lib/python3.10/site-packages/wandb/sdk/wandb_run.py", line 2101, in _finish
    with telemetry.context(run=self) as tel:
  File "/home/users/yz705/.local/lib/python3.10/site-packages/wandb/sdk/lib/telemetry.py", line 42, in __exit__
    self._run._telemetry_callback(self._obj)
  File "/home/users/yz705/.local/lib/python3.10/site-packages/wandb/sdk/wandb_run.py", line 792, in _telemetry_callback
    self._telemetry_flush()
  File "/home/users/yz705/.local/lib/python3.10/site-packages/wandb/sdk/wandb_run.py", line 803, in _telemetry_flush
    self._backend.interface._publish_telemetry(self._telemetry_obj)
  File "/home/users/yz705/.local/lib/python3.10/site-packages/wandb/sdk/interface/interface_shared.py", line 101, in _publish_telemetry
    self._publish(rec)
  File "/home/users/yz705/.local/lib/python3.10/site-packages/wandb/sdk/interface/interface_sock.py", line 51, in _publish
    self._sock_client.send_record_publish(record)
  File "/home/users/yz705/.local/lib/python3.10/site-packages/wandb/sdk/lib/sock_client.py", line 221, in send_record_publish
    self.send_server_request(server_req)
  File "/home/users/yz705/.local/lib/python3.10/site-packages/wandb/sdk/lib/sock_client.py", line 155, in send_server_request
    self._send_message(msg)
  File "/home/users/yz705/.local/lib/python3.10/site-packages/wandb/sdk/lib/sock_client.py", line 152, in _send_message
    self._sendall_with_error_handle(header + data)
  File "/home/users/yz705/.local/lib/python3.10/site-packages/wandb/sdk/lib/sock_client.py", line 130, in _sendall_with_error_handle
    sent = self._sock.send(data)
BrokenPipeError: [Errno 32] Broken pipe
wandb: Agent Starting Run: h22ip47e with config:
wandb: 	epochs: 80
wandb: 	lr: 1.0887945076090926
wandb: 	new_adj_dim: 10
wandb: 	numSampledCCs: 17
wandb: 	numSampledCycles: 25
wandb: 	pretrain_epochs: 80
Exception in thread Thread-19 (_run_job):
Traceback (most recent call last):
  File "/home/users/yz705/.local/lib/python3.10/site-packages/wandb/agents/pyagent.py", line 307, in _run_job
    self._function()
  File "/usr/project/xtmp/yz705/deep-topological-clustering/./graph_autoencoder.py", line 409, in one_tune_instance
    pretrain_labels_pred, train_labels_pred = train((train_loader, adj_matrices, labels_true))
TypeError: train() missing 1 required positional argument: 'dataset'

During handling of the above exception, another exception occurred:

Traceback (most recent call last):
  File "/usr/lib/python3.10/threading.py", line 1016, in _bootstrap_inner
    self.run()
  File "/usr/lib/python3.10/threading.py", line 953, in run
    self._target(*self._args, **self._kwargs)
  File "/home/users/yz705/.local/lib/python3.10/site-packages/wandb/agents/pyagent.py", line 312, in _run_job
    wandb.finish(exit_code=1)
  File "/home/users/yz705/.local/lib/python3.10/site-packages/wandb/sdk/wandb_run.py", line 4247, in finish
    wandb.run.finish(exit_code=exit_code, quiet=quiet)
  File "/home/users/yz705/.local/lib/python3.10/site-packages/wandb/sdk/wandb_run.py", line 449, in wrapper
    return func(self, *args, **kwargs)
  File "/home/users/yz705/.local/lib/python3.10/site-packages/wandb/sdk/wandb_run.py", line 390, in wrapper
    return func(self, *args, **kwargs)
  File "/home/users/yz705/.local/lib/python3.10/site-packages/wandb/sdk/wandb_run.py", line 2094, in finish
    return self._finish(exit_code, quiet)
  File "/home/users/yz705/.local/lib/python3.10/site-packages/wandb/sdk/wandb_run.py", line 2101, in _finish
    with telemetry.context(run=self) as tel:
  File "/home/users/yz705/.local/lib/python3.10/site-packages/wandb/sdk/lib/telemetry.py", line 42, in __exit__
    self._run._telemetry_callback(self._obj)
  File "/home/users/yz705/.local/lib/python3.10/site-packages/wandb/sdk/wandb_run.py", line 792, in _telemetry_callback
    self._telemetry_flush()
  File "/home/users/yz705/.local/lib/python3.10/site-packages/wandb/sdk/wandb_run.py", line 803, in _telemetry_flush
    self._backend.interface._publish_telemetry(self._telemetry_obj)
  File "/home/users/yz705/.local/lib/python3.10/site-packages/wandb/sdk/interface/interface_shared.py", line 101, in _publish_telemetry
    self._publish(rec)
  File "/home/users/yz705/.local/lib/python3.10/site-packages/wandb/sdk/interface/interface_sock.py", line 51, in _publish
    self._sock_client.send_record_publish(record)
  File "/home/users/yz705/.local/lib/python3.10/site-packages/wandb/sdk/lib/sock_client.py", line 221, in send_record_publish
    self.send_server_request(server_req)
  File "/home/users/yz705/.local/lib/python3.10/site-packages/wandb/sdk/lib/sock_client.py", line 155, in send_server_request
    self._send_message(msg)
  File "/home/users/yz705/.local/lib/python3.10/site-packages/wandb/sdk/lib/sock_client.py", line 152, in _send_message
    self._sendall_with_error_handle(header + data)
  File "/home/users/yz705/.local/lib/python3.10/site-packages/wandb/sdk/lib/sock_client.py", line 130, in _sendall_with_error_handle
    sent = self._sock.send(data)
BrokenPipeError: [Errno 32] Broken pipe
wandb: Sweep Agent: Waiting for job.
wandb: Job received.
wandb: Agent Starting Run: gj1uxxzr with config:
wandb: 	epochs: 100
wandb: 	lr: 1.0106120739805933
wandb: 	new_adj_dim: 11
wandb: 	numSampledCCs: 10
wandb: 	numSampledCycles: 40
wandb: 	pretrain_epochs: 60
Exception in thread Thread-20 (_run_job):
Traceback (most recent call last):
  File "/home/users/yz705/.local/lib/python3.10/site-packages/wandb/agents/pyagent.py", line 307, in _run_job
    self._function()
  File "/usr/project/xtmp/yz705/deep-topological-clustering/./graph_autoencoder.py", line 409, in one_tune_instance
    pretrain_labels_pred, train_labels_pred = train((train_loader, adj_matrices, labels_true))
TypeError: train() missing 1 required positional argument: 'dataset'

During handling of the above exception, another exception occurred:

Traceback (most recent call last):
  File "/usr/lib/python3.10/threading.py", line 1016, in _bootstrap_inner
    self.run()
  File "/usr/lib/python3.10/threading.py", line 953, in run
    self._target(*self._args, **self._kwargs)
  File "/home/users/yz705/.local/lib/python3.10/site-packages/wandb/agents/pyagent.py", line 312, in _run_job
    wandb.finish(exit_code=1)
  File "/home/users/yz705/.local/lib/python3.10/site-packages/wandb/sdk/wandb_run.py", line 4247, in finish
    wandb.run.finish(exit_code=exit_code, quiet=quiet)
  File "/home/users/yz705/.local/lib/python3.10/site-packages/wandb/sdk/wandb_run.py", line 449, in wrapper
    return func(self, *args, **kwargs)
  File "/home/users/yz705/.local/lib/python3.10/site-packages/wandb/sdk/wandb_run.py", line 390, in wrapper
    return func(self, *args, **kwargs)
  File "/home/users/yz705/.local/lib/python3.10/site-packages/wandb/sdk/wandb_run.py", line 2094, in finish
    return self._finish(exit_code, quiet)
  File "/home/users/yz705/.local/lib/python3.10/site-packages/wandb/sdk/wandb_run.py", line 2101, in _finish
    with telemetry.context(run=self) as tel:
  File "/home/users/yz705/.local/lib/python3.10/site-packages/wandb/sdk/lib/telemetry.py", line 42, in __exit__
    self._run._telemetry_callback(self._obj)
  File "/home/users/yz705/.local/lib/python3.10/site-packages/wandb/sdk/wandb_run.py", line 792, in _telemetry_callback
    self._telemetry_flush()
  File "/home/users/yz705/.local/lib/python3.10/site-packages/wandb/sdk/wandb_run.py", line 803, in _telemetry_flush
    self._backend.interface._publish_telemetry(self._telemetry_obj)
  File "/home/users/yz705/.local/lib/python3.10/site-packages/wandb/sdk/interface/interface_shared.py", line 101, in _publish_telemetry
    self._publish(rec)
  File "/home/users/yz705/.local/lib/python3.10/site-packages/wandb/sdk/interface/interface_sock.py", line 51, in _publish
    self._sock_client.send_record_publish(record)
  File "/home/users/yz705/.local/lib/python3.10/site-packages/wandb/sdk/lib/sock_client.py", line 221, in send_record_publish
    self.send_server_request(server_req)
  File "/home/users/yz705/.local/lib/python3.10/site-packages/wandb/sdk/lib/sock_client.py", line 155, in send_server_request
    self._send_message(msg)
  File "/home/users/yz705/.local/lib/python3.10/site-packages/wandb/sdk/lib/sock_client.py", line 152, in _send_message
    self._sendall_with_error_handle(header + data)
  File "/home/users/yz705/.local/lib/python3.10/site-packages/wandb/sdk/lib/sock_client.py", line 130, in _sendall_with_error_handle
    sent = self._sock.send(data)
BrokenPipeError: [Errno 32] Broken pipe
wandb: Agent Starting Run: tzojie25 with config:
wandb: 	epochs: 80
wandb: 	lr: 1.0485855422243402
wandb: 	new_adj_dim: 6
wandb: 	numSampledCCs: 5
wandb: 	numSampledCycles: 32
wandb: 	pretrain_epochs: 90
Exception in thread Thread-21 (_run_job):
Traceback (most recent call last):
  File "/home/users/yz705/.local/lib/python3.10/site-packages/wandb/agents/pyagent.py", line 307, in _run_job
    self._function()
  File "/usr/project/xtmp/yz705/deep-topological-clustering/./graph_autoencoder.py", line 409, in one_tune_instance
    pretrain_labels_pred, train_labels_pred = train((train_loader, adj_matrices, labels_true))
TypeError: train() missing 1 required positional argument: 'dataset'

During handling of the above exception, another exception occurred:

Traceback (most recent call last):
  File "/usr/lib/python3.10/threading.py", line 1016, in _bootstrap_inner
    self.run()
  File "/usr/lib/python3.10/threading.py", line 953, in run
    self._target(*self._args, **self._kwargs)
  File "/home/users/yz705/.local/lib/python3.10/site-packages/wandb/agents/pyagent.py", line 312, in _run_job
    wandb.finish(exit_code=1)
  File "/home/users/yz705/.local/lib/python3.10/site-packages/wandb/sdk/wandb_run.py", line 4247, in finish
    wandb.run.finish(exit_code=exit_code, quiet=quiet)
  File "/home/users/yz705/.local/lib/python3.10/site-packages/wandb/sdk/wandb_run.py", line 449, in wrapper
    return func(self, *args, **kwargs)
  File "/home/users/yz705/.local/lib/python3.10/site-packages/wandb/sdk/wandb_run.py", line 390, in wrapper
    return func(self, *args, **kwargs)
  File "/home/users/yz705/.local/lib/python3.10/site-packages/wandb/sdk/wandb_run.py", line 2094, in finish
    return self._finish(exit_code, quiet)
  File "/home/users/yz705/.local/lib/python3.10/site-packages/wandb/sdk/wandb_run.py", line 2101, in _finish
    with telemetry.context(run=self) as tel:
  File "/home/users/yz705/.local/lib/python3.10/site-packages/wandb/sdk/lib/telemetry.py", line 42, in __exit__
    self._run._telemetry_callback(self._obj)
  File "/home/users/yz705/.local/lib/python3.10/site-packages/wandb/sdk/wandb_run.py", line 792, in _telemetry_callback
    self._telemetry_flush()
  File "/home/users/yz705/.local/lib/python3.10/site-packages/wandb/sdk/wandb_run.py", line 803, in _telemetry_flush
    self._backend.interface._publish_telemetry(self._telemetry_obj)
  File "/home/users/yz705/.local/lib/python3.10/site-packages/wandb/sdk/interface/interface_shared.py", line 101, in _publish_telemetry
    self._publish(rec)
  File "/home/users/yz705/.local/lib/python3.10/site-packages/wandb/sdk/interface/interface_sock.py", line 51, in _publish
    self._sock_client.send_record_publish(record)
  File "/home/users/yz705/.local/lib/python3.10/site-packages/wandb/sdk/lib/sock_client.py", line 221, in send_record_publish
    self.send_server_request(server_req)
  File "/home/users/yz705/.local/lib/python3.10/site-packages/wandb/sdk/lib/sock_client.py", line 155, in send_server_request
    self._send_message(msg)
  File "/home/users/yz705/.local/lib/python3.10/site-packages/wandb/sdk/lib/sock_client.py", line 152, in _send_message
    self._sendall_with_error_handle(header + data)
  File "/home/users/yz705/.local/lib/python3.10/site-packages/wandb/sdk/lib/sock_client.py", line 130, in _sendall_with_error_handle
    sent = self._sock.send(data)
BrokenPipeError: [Errno 32] Broken pipe
wandb: Sweep Agent: Waiting for job.
wandb: Job received.
wandb: Agent Starting Run: g8nxljyj with config:
wandb: 	epochs: 110
wandb: 	lr: 1.05584511148301
wandb: 	new_adj_dim: 10
wandb: 	numSampledCCs: 9
wandb: 	numSampledCycles: 50
wandb: 	pretrain_epochs: 80
Exception in thread Thread-22 (_run_job):
Traceback (most recent call last):
  File "/home/users/yz705/.local/lib/python3.10/site-packages/wandb/agents/pyagent.py", line 307, in _run_job
    self._function()
  File "/usr/project/xtmp/yz705/deep-topological-clustering/./graph_autoencoder.py", line 409, in one_tune_instance
    pretrain_labels_pred, train_labels_pred = train((train_loader, adj_matrices, labels_true))
TypeError: train() missing 1 required positional argument: 'dataset'

During handling of the above exception, another exception occurred:

Traceback (most recent call last):
  File "/usr/lib/python3.10/threading.py", line 1016, in _bootstrap_inner
    self.run()
  File "/usr/lib/python3.10/threading.py", line 953, in run
    self._target(*self._args, **self._kwargs)
  File "/home/users/yz705/.local/lib/python3.10/site-packages/wandb/agents/pyagent.py", line 312, in _run_job
    wandb.finish(exit_code=1)
  File "/home/users/yz705/.local/lib/python3.10/site-packages/wandb/sdk/wandb_run.py", line 4247, in finish
    wandb.run.finish(exit_code=exit_code, quiet=quiet)
  File "/home/users/yz705/.local/lib/python3.10/site-packages/wandb/sdk/wandb_run.py", line 449, in wrapper
    return func(self, *args, **kwargs)
  File "/home/users/yz705/.local/lib/python3.10/site-packages/wandb/sdk/wandb_run.py", line 390, in wrapper
    return func(self, *args, **kwargs)
  File "/home/users/yz705/.local/lib/python3.10/site-packages/wandb/sdk/wandb_run.py", line 2094, in finish
    return self._finish(exit_code, quiet)
  File "/home/users/yz705/.local/lib/python3.10/site-packages/wandb/sdk/wandb_run.py", line 2101, in _finish
    with telemetry.context(run=self) as tel:
  File "/home/users/yz705/.local/lib/python3.10/site-packages/wandb/sdk/lib/telemetry.py", line 42, in __exit__
    self._run._telemetry_callback(self._obj)
  File "/home/users/yz705/.local/lib/python3.10/site-packages/wandb/sdk/wandb_run.py", line 792, in _telemetry_callback
    self._telemetry_flush()
  File "/home/users/yz705/.local/lib/python3.10/site-packages/wandb/sdk/wandb_run.py", line 803, in _telemetry_flush
    self._backend.interface._publish_telemetry(self._telemetry_obj)
  File "/home/users/yz705/.local/lib/python3.10/site-packages/wandb/sdk/interface/interface_shared.py", line 101, in _publish_telemetry
    self._publish(rec)
  File "/home/users/yz705/.local/lib/python3.10/site-packages/wandb/sdk/interface/interface_sock.py", line 51, in _publish
    self._sock_client.send_record_publish(record)
  File "/home/users/yz705/.local/lib/python3.10/site-packages/wandb/sdk/lib/sock_client.py", line 221, in send_record_publish
    self.send_server_request(server_req)
  File "/home/users/yz705/.local/lib/python3.10/site-packages/wandb/sdk/lib/sock_client.py", line 155, in send_server_request
    self._send_message(msg)
  File "/home/users/yz705/.local/lib/python3.10/site-packages/wandb/sdk/lib/sock_client.py", line 152, in _send_message
    self._sendall_with_error_handle(header + data)
  File "/home/users/yz705/.local/lib/python3.10/site-packages/wandb/sdk/lib/sock_client.py", line 130, in _sendall_with_error_handle
    sent = self._sock.send(data)
BrokenPipeError: [Errno 32] Broken pipe
wandb: Agent Starting Run: mf1nnjuq with config:
wandb: 	epochs: 60
wandb: 	lr: 1.000237686585235
wandb: 	new_adj_dim: 9
wandb: 	numSampledCCs: 9
wandb: 	numSampledCycles: 33
wandb: 	pretrain_epochs: 50
Exception in thread Thread-23 (_run_job):
Traceback (most recent call last):
  File "/home/users/yz705/.local/lib/python3.10/site-packages/wandb/agents/pyagent.py", line 307, in _run_job
    self._function()
  File "/usr/project/xtmp/yz705/deep-topological-clustering/./graph_autoencoder.py", line 409, in one_tune_instance
    pretrain_labels_pred, train_labels_pred = train((train_loader, adj_matrices, labels_true))
TypeError: train() missing 1 required positional argument: 'dataset'

During handling of the above exception, another exception occurred:

Traceback (most recent call last):
  File "/usr/lib/python3.10/threading.py", line 1016, in _bootstrap_inner
    self.run()
  File "/usr/lib/python3.10/threading.py", line 953, in run
    self._target(*self._args, **self._kwargs)
  File "/home/users/yz705/.local/lib/python3.10/site-packages/wandb/agents/pyagent.py", line 312, in _run_job
    wandb.finish(exit_code=1)
  File "/home/users/yz705/.local/lib/python3.10/site-packages/wandb/sdk/wandb_run.py", line 4247, in finish
    wandb.run.finish(exit_code=exit_code, quiet=quiet)
  File "/home/users/yz705/.local/lib/python3.10/site-packages/wandb/sdk/wandb_run.py", line 449, in wrapper
    return func(self, *args, **kwargs)
  File "/home/users/yz705/.local/lib/python3.10/site-packages/wandb/sdk/wandb_run.py", line 390, in wrapper
    return func(self, *args, **kwargs)
  File "/home/users/yz705/.local/lib/python3.10/site-packages/wandb/sdk/wandb_run.py", line 2094, in finish
    return self._finish(exit_code, quiet)
  File "/home/users/yz705/.local/lib/python3.10/site-packages/wandb/sdk/wandb_run.py", line 2101, in _finish
    with telemetry.context(run=self) as tel:
  File "/home/users/yz705/.local/lib/python3.10/site-packages/wandb/sdk/lib/telemetry.py", line 42, in __exit__
    self._run._telemetry_callback(self._obj)
  File "/home/users/yz705/.local/lib/python3.10/site-packages/wandb/sdk/wandb_run.py", line 792, in _telemetry_callback
    self._telemetry_flush()
  File "/home/users/yz705/.local/lib/python3.10/site-packages/wandb/sdk/wandb_run.py", line 803, in _telemetry_flush
    self._backend.interface._publish_telemetry(self._telemetry_obj)
  File "/home/users/yz705/.local/lib/python3.10/site-packages/wandb/sdk/interface/interface_shared.py", line 101, in _publish_telemetry
    self._publish(rec)
  File "/home/users/yz705/.local/lib/python3.10/site-packages/wandb/sdk/interface/interface_sock.py", line 51, in _publish
    self._sock_client.send_record_publish(record)
  File "/home/users/yz705/.local/lib/python3.10/site-packages/wandb/sdk/lib/sock_client.py", line 221, in send_record_publish
    self.send_server_request(server_req)
  File "/home/users/yz705/.local/lib/python3.10/site-packages/wandb/sdk/lib/sock_client.py", line 155, in send_server_request
    self._send_message(msg)
  File "/home/users/yz705/.local/lib/python3.10/site-packages/wandb/sdk/lib/sock_client.py", line 152, in _send_message
    self._sendall_with_error_handle(header + data)
  File "/home/users/yz705/.local/lib/python3.10/site-packages/wandb/sdk/lib/sock_client.py", line 130, in _sendall_with_error_handle
    sent = self._sock.send(data)
BrokenPipeError: [Errno 32] Broken pipe
wandb: Sweep Agent: Waiting for job.
wandb: Job received.
wandb: Agent Starting Run: cy5ct06t with config:
wandb: 	epochs: 170
wandb: 	lr: 1.0103660218725494
wandb: 	new_adj_dim: 14
wandb: 	numSampledCCs: 13
wandb: 	numSampledCycles: 39
wandb: 	pretrain_epochs: 80
Exception in thread Thread-24 (_run_job):
Traceback (most recent call last):
  File "/home/users/yz705/.local/lib/python3.10/site-packages/wandb/agents/pyagent.py", line 307, in _run_job
    self._function()
  File "/usr/project/xtmp/yz705/deep-topological-clustering/./graph_autoencoder.py", line 409, in one_tune_instance
    pretrain_labels_pred, train_labels_pred = train((train_loader, adj_matrices, labels_true))
TypeError: train() missing 1 required positional argument: 'dataset'

During handling of the above exception, another exception occurred:

Traceback (most recent call last):
  File "/usr/lib/python3.10/threading.py", line 1016, in _bootstrap_inner
    self.run()
  File "/usr/lib/python3.10/threading.py", line 953, in run
    self._target(*self._args, **self._kwargs)
  File "/home/users/yz705/.local/lib/python3.10/site-packages/wandb/agents/pyagent.py", line 312, in _run_job
    wandb.finish(exit_code=1)
  File "/home/users/yz705/.local/lib/python3.10/site-packages/wandb/sdk/wandb_run.py", line 4247, in finish
    wandb.run.finish(exit_code=exit_code, quiet=quiet)
  File "/home/users/yz705/.local/lib/python3.10/site-packages/wandb/sdk/wandb_run.py", line 449, in wrapper
    return func(self, *args, **kwargs)
  File "/home/users/yz705/.local/lib/python3.10/site-packages/wandb/sdk/wandb_run.py", line 390, in wrapper
    return func(self, *args, **kwargs)
  File "/home/users/yz705/.local/lib/python3.10/site-packages/wandb/sdk/wandb_run.py", line 2094, in finish
    return self._finish(exit_code, quiet)
  File "/home/users/yz705/.local/lib/python3.10/site-packages/wandb/sdk/wandb_run.py", line 2101, in _finish
    with telemetry.context(run=self) as tel:
  File "/home/users/yz705/.local/lib/python3.10/site-packages/wandb/sdk/lib/telemetry.py", line 42, in __exit__
    self._run._telemetry_callback(self._obj)
  File "/home/users/yz705/.local/lib/python3.10/site-packages/wandb/sdk/wandb_run.py", line 792, in _telemetry_callback
    self._telemetry_flush()
  File "/home/users/yz705/.local/lib/python3.10/site-packages/wandb/sdk/wandb_run.py", line 803, in _telemetry_flush
    self._backend.interface._publish_telemetry(self._telemetry_obj)
  File "/home/users/yz705/.local/lib/python3.10/site-packages/wandb/sdk/interface/interface_shared.py", line 101, in _publish_telemetry
    self._publish(rec)
  File "/home/users/yz705/.local/lib/python3.10/site-packages/wandb/sdk/interface/interface_sock.py", line 51, in _publish
    self._sock_client.send_record_publish(record)
  File "/home/users/yz705/.local/lib/python3.10/site-packages/wandb/sdk/lib/sock_client.py", line 221, in send_record_publish
    self.send_server_request(server_req)
  File "/home/users/yz705/.local/lib/python3.10/site-packages/wandb/sdk/lib/sock_client.py", line 155, in send_server_request
    self._send_message(msg)
  File "/home/users/yz705/.local/lib/python3.10/site-packages/wandb/sdk/lib/sock_client.py", line 152, in _send_message
    self._sendall_with_error_handle(header + data)
  File "/home/users/yz705/.local/lib/python3.10/site-packages/wandb/sdk/lib/sock_client.py", line 130, in _sendall_with_error_handle
    sent = self._sock.send(data)
BrokenPipeError: [Errno 32] Broken pipe
wandb: Agent Starting Run: u197vx1j with config:
wandb: 	epochs: 90
wandb: 	lr: 1.070179374433846
wandb: 	new_adj_dim: 14
wandb: 	numSampledCCs: 5
wandb: 	numSampledCycles: 52
wandb: 	pretrain_epochs: 50
Exception in thread Thread-25 (_run_job):
Traceback (most recent call last):
  File "/home/users/yz705/.local/lib/python3.10/site-packages/wandb/agents/pyagent.py", line 307, in _run_job
    self._function()
  File "/usr/project/xtmp/yz705/deep-topological-clustering/./graph_autoencoder.py", line 409, in one_tune_instance
    pretrain_labels_pred, train_labels_pred = train((train_loader, adj_matrices, labels_true))
TypeError: train() missing 1 required positional argument: 'dataset'

During handling of the above exception, another exception occurred:

Traceback (most recent call last):
  File "/usr/lib/python3.10/threading.py", line 1016, in _bootstrap_inner
    self.run()
  File "/usr/lib/python3.10/threading.py", line 953, in run
    self._target(*self._args, **self._kwargs)
  File "/home/users/yz705/.local/lib/python3.10/site-packages/wandb/agents/pyagent.py", line 312, in _run_job
    wandb.finish(exit_code=1)
  File "/home/users/yz705/.local/lib/python3.10/site-packages/wandb/sdk/wandb_run.py", line 4247, in finish
    wandb.run.finish(exit_code=exit_code, quiet=quiet)
  File "/home/users/yz705/.local/lib/python3.10/site-packages/wandb/sdk/wandb_run.py", line 449, in wrapper
    return func(self, *args, **kwargs)
  File "/home/users/yz705/.local/lib/python3.10/site-packages/wandb/sdk/wandb_run.py", line 390, in wrapper
    return func(self, *args, **kwargs)
  File "/home/users/yz705/.local/lib/python3.10/site-packages/wandb/sdk/wandb_run.py", line 2094, in finish
    return self._finish(exit_code, quiet)
  File "/home/users/yz705/.local/lib/python3.10/site-packages/wandb/sdk/wandb_run.py", line 2101, in _finish
    with telemetry.context(run=self) as tel:
  File "/home/users/yz705/.local/lib/python3.10/site-packages/wandb/sdk/lib/telemetry.py", line 42, in __exit__
    self._run._telemetry_callback(self._obj)
  File "/home/users/yz705/.local/lib/python3.10/site-packages/wandb/sdk/wandb_run.py", line 792, in _telemetry_callback
    self._telemetry_flush()
  File "/home/users/yz705/.local/lib/python3.10/site-packages/wandb/sdk/wandb_run.py", line 803, in _telemetry_flush
    self._backend.interface._publish_telemetry(self._telemetry_obj)
  File "/home/users/yz705/.local/lib/python3.10/site-packages/wandb/sdk/interface/interface_shared.py", line 101, in _publish_telemetry
    self._publish(rec)
  File "/home/users/yz705/.local/lib/python3.10/site-packages/wandb/sdk/interface/interface_sock.py", line 51, in _publish
    self._sock_client.send_record_publish(record)
  File "/home/users/yz705/.local/lib/python3.10/site-packages/wandb/sdk/lib/sock_client.py", line 221, in send_record_publish
    self.send_server_request(server_req)
  File "/home/users/yz705/.local/lib/python3.10/site-packages/wandb/sdk/lib/sock_client.py", line 155, in send_server_request
    self._send_message(msg)
  File "/home/users/yz705/.local/lib/python3.10/site-packages/wandb/sdk/lib/sock_client.py", line 152, in _send_message
    self._sendall_with_error_handle(header + data)
  File "/home/users/yz705/.local/lib/python3.10/site-packages/wandb/sdk/lib/sock_client.py", line 130, in _sendall_with_error_handle
    sent = self._sock.send(data)
BrokenPipeError: [Errno 32] Broken pipe
wandb: Sweep Agent: Waiting for job.
wandb: Job received.
wandb: Agent Starting Run: 5vci4rv7 with config:
wandb: 	epochs: 60
wandb: 	lr: 1.0189079920873538
wandb: 	new_adj_dim: 6
wandb: 	numSampledCCs: 11
wandb: 	numSampledCycles: 42
wandb: 	pretrain_epochs: 90
Exception in thread Thread-26 (_run_job):
Traceback (most recent call last):
  File "/home/users/yz705/.local/lib/python3.10/site-packages/wandb/agents/pyagent.py", line 307, in _run_job
    self._function()
  File "/usr/project/xtmp/yz705/deep-topological-clustering/./graph_autoencoder.py", line 409, in one_tune_instance
    pretrain_labels_pred, train_labels_pred = train((train_loader, adj_matrices, labels_true))
TypeError: train() missing 1 required positional argument: 'dataset'

During handling of the above exception, another exception occurred:

Traceback (most recent call last):
  File "/usr/lib/python3.10/threading.py", line 1016, in _bootstrap_inner
    self.run()
  File "/usr/lib/python3.10/threading.py", line 953, in run
    self._target(*self._args, **self._kwargs)
  File "/home/users/yz705/.local/lib/python3.10/site-packages/wandb/agents/pyagent.py", line 312, in _run_job
    wandb.finish(exit_code=1)
  File "/home/users/yz705/.local/lib/python3.10/site-packages/wandb/sdk/wandb_run.py", line 4247, in finish
    wandb.run.finish(exit_code=exit_code, quiet=quiet)
  File "/home/users/yz705/.local/lib/python3.10/site-packages/wandb/sdk/wandb_run.py", line 449, in wrapper
    return func(self, *args, **kwargs)
  File "/home/users/yz705/.local/lib/python3.10/site-packages/wandb/sdk/wandb_run.py", line 390, in wrapper
    return func(self, *args, **kwargs)
  File "/home/users/yz705/.local/lib/python3.10/site-packages/wandb/sdk/wandb_run.py", line 2094, in finish
    return self._finish(exit_code, quiet)
  File "/home/users/yz705/.local/lib/python3.10/site-packages/wandb/sdk/wandb_run.py", line 2101, in _finish
    with telemetry.context(run=self) as tel:
  File "/home/users/yz705/.local/lib/python3.10/site-packages/wandb/sdk/lib/telemetry.py", line 42, in __exit__
    self._run._telemetry_callback(self._obj)
  File "/home/users/yz705/.local/lib/python3.10/site-packages/wandb/sdk/wandb_run.py", line 792, in _telemetry_callback
    self._telemetry_flush()
  File "/home/users/yz705/.local/lib/python3.10/site-packages/wandb/sdk/wandb_run.py", line 803, in _telemetry_flush
    self._backend.interface._publish_telemetry(self._telemetry_obj)
  File "/home/users/yz705/.local/lib/python3.10/site-packages/wandb/sdk/interface/interface_shared.py", line 101, in _publish_telemetry
    self._publish(rec)
  File "/home/users/yz705/.local/lib/python3.10/site-packages/wandb/sdk/interface/interface_sock.py", line 51, in _publish
    self._sock_client.send_record_publish(record)
  File "/home/users/yz705/.local/lib/python3.10/site-packages/wandb/sdk/lib/sock_client.py", line 221, in send_record_publish
    self.send_server_request(server_req)
  File "/home/users/yz705/.local/lib/python3.10/site-packages/wandb/sdk/lib/sock_client.py", line 155, in send_server_request
    self._send_message(msg)
  File "/home/users/yz705/.local/lib/python3.10/site-packages/wandb/sdk/lib/sock_client.py", line 152, in _send_message
    self._sendall_with_error_handle(header + data)
  File "/home/users/yz705/.local/lib/python3.10/site-packages/wandb/sdk/lib/sock_client.py", line 130, in _sendall_with_error_handle
    sent = self._sock.send(data)
BrokenPipeError: [Errno 32] Broken pipe
wandb: Sweep Agent: Waiting for job.
wandb: Job received.
wandb: Agent Starting Run: 6m2wsv6g with config:
wandb: 	epochs: 100
wandb: 	lr: 1.0583036604817266
wandb: 	new_adj_dim: 5
wandb: 	numSampledCCs: 15
wandb: 	numSampledCycles: 59
wandb: 	pretrain_epochs: 50
Exception in thread Thread-27 (_run_job):
Traceback (most recent call last):
  File "/home/users/yz705/.local/lib/python3.10/site-packages/wandb/agents/pyagent.py", line 307, in _run_job
    self._function()
  File "/usr/project/xtmp/yz705/deep-topological-clustering/./graph_autoencoder.py", line 409, in one_tune_instance
    pretrain_labels_pred, train_labels_pred = train((train_loader, adj_matrices, labels_true))
TypeError: train() missing 1 required positional argument: 'dataset'

During handling of the above exception, another exception occurred:

Traceback (most recent call last):
  File "/usr/lib/python3.10/threading.py", line 1016, in _bootstrap_inner
    self.run()
  File "/usr/lib/python3.10/threading.py", line 953, in run
    self._target(*self._args, **self._kwargs)
  File "/home/users/yz705/.local/lib/python3.10/site-packages/wandb/agents/pyagent.py", line 312, in _run_job
    wandb.finish(exit_code=1)
  File "/home/users/yz705/.local/lib/python3.10/site-packages/wandb/sdk/wandb_run.py", line 4247, in finish
    wandb.run.finish(exit_code=exit_code, quiet=quiet)
  File "/home/users/yz705/.local/lib/python3.10/site-packages/wandb/sdk/wandb_run.py", line 449, in wrapper
    return func(self, *args, **kwargs)
  File "/home/users/yz705/.local/lib/python3.10/site-packages/wandb/sdk/wandb_run.py", line 390, in wrapper
    return func(self, *args, **kwargs)
  File "/home/users/yz705/.local/lib/python3.10/site-packages/wandb/sdk/wandb_run.py", line 2094, in finish
    return self._finish(exit_code, quiet)
  File "/home/users/yz705/.local/lib/python3.10/site-packages/wandb/sdk/wandb_run.py", line 2101, in _finish
    with telemetry.context(run=self) as tel:
  File "/home/users/yz705/.local/lib/python3.10/site-packages/wandb/sdk/lib/telemetry.py", line 42, in __exit__
    self._run._telemetry_callback(self._obj)
  File "/home/users/yz705/.local/lib/python3.10/site-packages/wandb/sdk/wandb_run.py", line 792, in _telemetry_callback
    self._telemetry_flush()
  File "/home/users/yz705/.local/lib/python3.10/site-packages/wandb/sdk/wandb_run.py", line 803, in _telemetry_flush
    self._backend.interface._publish_telemetry(self._telemetry_obj)
  File "/home/users/yz705/.local/lib/python3.10/site-packages/wandb/sdk/interface/interface_shared.py", line 101, in _publish_telemetry
    self._publish(rec)
  File "/home/users/yz705/.local/lib/python3.10/site-packages/wandb/sdk/interface/interface_sock.py", line 51, in _publish
    self._sock_client.send_record_publish(record)
  File "/home/users/yz705/.local/lib/python3.10/site-packages/wandb/sdk/lib/sock_client.py", line 221, in send_record_publish
    self.send_server_request(server_req)
  File "/home/users/yz705/.local/lib/python3.10/site-packages/wandb/sdk/lib/sock_client.py", line 155, in send_server_request
    self._send_message(msg)
  File "/home/users/yz705/.local/lib/python3.10/site-packages/wandb/sdk/lib/sock_client.py", line 152, in _send_message
    self._sendall_with_error_handle(header + data)
  File "/home/users/yz705/.local/lib/python3.10/site-packages/wandb/sdk/lib/sock_client.py", line 130, in _sendall_with_error_handle
    sent = self._sock.send(data)
BrokenPipeError: [Errno 32] Broken pipe
wandb: Agent Starting Run: exz6z3cg with config:
wandb: 	epochs: 150
wandb: 	lr: 1.08125410025419
wandb: 	new_adj_dim: 14
wandb: 	numSampledCCs: 6
wandb: 	numSampledCycles: 50
wandb: 	pretrain_epochs: 40
Exception in thread Thread-28 (_run_job):
Traceback (most recent call last):
  File "/home/users/yz705/.local/lib/python3.10/site-packages/wandb/agents/pyagent.py", line 307, in _run_job
    self._function()
  File "/usr/project/xtmp/yz705/deep-topological-clustering/./graph_autoencoder.py", line 409, in one_tune_instance
    pretrain_labels_pred, train_labels_pred = train((train_loader, adj_matrices, labels_true))
TypeError: train() missing 1 required positional argument: 'dataset'

During handling of the above exception, another exception occurred:

Traceback (most recent call last):
  File "/usr/lib/python3.10/threading.py", line 1016, in _bootstrap_inner
    self.run()
  File "/usr/lib/python3.10/threading.py", line 953, in run
    self._target(*self._args, **self._kwargs)
  File "/home/users/yz705/.local/lib/python3.10/site-packages/wandb/agents/pyagent.py", line 312, in _run_job
    wandb.finish(exit_code=1)
  File "/home/users/yz705/.local/lib/python3.10/site-packages/wandb/sdk/wandb_run.py", line 4247, in finish
    wandb.run.finish(exit_code=exit_code, quiet=quiet)
  File "/home/users/yz705/.local/lib/python3.10/site-packages/wandb/sdk/wandb_run.py", line 449, in wrapper
    return func(self, *args, **kwargs)
  File "/home/users/yz705/.local/lib/python3.10/site-packages/wandb/sdk/wandb_run.py", line 390, in wrapper
    return func(self, *args, **kwargs)
  File "/home/users/yz705/.local/lib/python3.10/site-packages/wandb/sdk/wandb_run.py", line 2094, in finish
    return self._finish(exit_code, quiet)
  File "/home/users/yz705/.local/lib/python3.10/site-packages/wandb/sdk/wandb_run.py", line 2101, in _finish
    with telemetry.context(run=self) as tel:
  File "/home/users/yz705/.local/lib/python3.10/site-packages/wandb/sdk/lib/telemetry.py", line 42, in __exit__
    self._run._telemetry_callback(self._obj)
  File "/home/users/yz705/.local/lib/python3.10/site-packages/wandb/sdk/wandb_run.py", line 792, in _telemetry_callback
    self._telemetry_flush()
  File "/home/users/yz705/.local/lib/python3.10/site-packages/wandb/sdk/wandb_run.py", line 803, in _telemetry_flush
    self._backend.interface._publish_telemetry(self._telemetry_obj)
  File "/home/users/yz705/.local/lib/python3.10/site-packages/wandb/sdk/interface/interface_shared.py", line 101, in _publish_telemetry
    self._publish(rec)
  File "/home/users/yz705/.local/lib/python3.10/site-packages/wandb/sdk/interface/interface_sock.py", line 51, in _publish
    self._sock_client.send_record_publish(record)
  File "/home/users/yz705/.local/lib/python3.10/site-packages/wandb/sdk/lib/sock_client.py", line 221, in send_record_publish
    self.send_server_request(server_req)
  File "/home/users/yz705/.local/lib/python3.10/site-packages/wandb/sdk/lib/sock_client.py", line 155, in send_server_request
    self._send_message(msg)
  File "/home/users/yz705/.local/lib/python3.10/site-packages/wandb/sdk/lib/sock_client.py", line 152, in _send_message
    self._sendall_with_error_handle(header + data)
  File "/home/users/yz705/.local/lib/python3.10/site-packages/wandb/sdk/lib/sock_client.py", line 130, in _sendall_with_error_handle
    sent = self._sock.send(data)
BrokenPipeError: [Errno 32] Broken pipe
wandb: Sweep Agent: Waiting for job.
wandb: Job received.
wandb: Agent Starting Run: e0w2lzzg with config:
wandb: 	epochs: 90
wandb: 	lr: 1.0026566959880563
wandb: 	new_adj_dim: 11
wandb: 	numSampledCCs: 4
wandb: 	numSampledCycles: 33
wandb: 	pretrain_epochs: 90
Exception in thread Thread-29 (_run_job):
Traceback (most recent call last):
  File "/home/users/yz705/.local/lib/python3.10/site-packages/wandb/agents/pyagent.py", line 307, in _run_job
    self._function()
  File "/usr/project/xtmp/yz705/deep-topological-clustering/./graph_autoencoder.py", line 409, in one_tune_instance
    pretrain_labels_pred, train_labels_pred = train((train_loader, adj_matrices, labels_true))
TypeError: train() missing 1 required positional argument: 'dataset'

During handling of the above exception, another exception occurred:

Traceback (most recent call last):
  File "/usr/lib/python3.10/threading.py", line 1016, in _bootstrap_inner
    self.run()
  File "/usr/lib/python3.10/threading.py", line 953, in run
    self._target(*self._args, **self._kwargs)
  File "/home/users/yz705/.local/lib/python3.10/site-packages/wandb/agents/pyagent.py", line 312, in _run_job
    wandb.finish(exit_code=1)
  File "/home/users/yz705/.local/lib/python3.10/site-packages/wandb/sdk/wandb_run.py", line 4247, in finish
    wandb.run.finish(exit_code=exit_code, quiet=quiet)
  File "/home/users/yz705/.local/lib/python3.10/site-packages/wandb/sdk/wandb_run.py", line 449, in wrapper
    return func(self, *args, **kwargs)
  File "/home/users/yz705/.local/lib/python3.10/site-packages/wandb/sdk/wandb_run.py", line 390, in wrapper
    return func(self, *args, **kwargs)
  File "/home/users/yz705/.local/lib/python3.10/site-packages/wandb/sdk/wandb_run.py", line 2094, in finish
    return self._finish(exit_code, quiet)
  File "/home/users/yz705/.local/lib/python3.10/site-packages/wandb/sdk/wandb_run.py", line 2101, in _finish
    with telemetry.context(run=self) as tel:
  File "/home/users/yz705/.local/lib/python3.10/site-packages/wandb/sdk/lib/telemetry.py", line 42, in __exit__
    self._run._telemetry_callback(self._obj)
  File "/home/users/yz705/.local/lib/python3.10/site-packages/wandb/sdk/wandb_run.py", line 792, in _telemetry_callback
    self._telemetry_flush()
  File "/home/users/yz705/.local/lib/python3.10/site-packages/wandb/sdk/wandb_run.py", line 803, in _telemetry_flush
    self._backend.interface._publish_telemetry(self._telemetry_obj)
  File "/home/users/yz705/.local/lib/python3.10/site-packages/wandb/sdk/interface/interface_shared.py", line 101, in _publish_telemetry
    self._publish(rec)
  File "/home/users/yz705/.local/lib/python3.10/site-packages/wandb/sdk/interface/interface_sock.py", line 51, in _publish
    self._sock_client.send_record_publish(record)
  File "/home/users/yz705/.local/lib/python3.10/site-packages/wandb/sdk/lib/sock_client.py", line 221, in send_record_publish
    self.send_server_request(server_req)
  File "/home/users/yz705/.local/lib/python3.10/site-packages/wandb/sdk/lib/sock_client.py", line 155, in send_server_request
    self._send_message(msg)
  File "/home/users/yz705/.local/lib/python3.10/site-packages/wandb/sdk/lib/sock_client.py", line 152, in _send_message
    self._sendall_with_error_handle(header + data)
  File "/home/users/yz705/.local/lib/python3.10/site-packages/wandb/sdk/lib/sock_client.py", line 130, in _sendall_with_error_handle
    sent = self._sock.send(data)
BrokenPipeError: [Errno 32] Broken pipe
wandb: Agent Starting Run: 63q02rg7 with config:
wandb: 	epochs: 130
wandb: 	lr: 1.0077708710194722
wandb: 	new_adj_dim: 5
wandb: 	numSampledCCs: 13
wandb: 	numSampledCycles: 36
wandb: 	pretrain_epochs: 40
Exception in thread Thread-30 (_run_job):
Traceback (most recent call last):
  File "/home/users/yz705/.local/lib/python3.10/site-packages/wandb/agents/pyagent.py", line 307, in _run_job
    self._function()
  File "/usr/project/xtmp/yz705/deep-topological-clustering/./graph_autoencoder.py", line 409, in one_tune_instance
    pretrain_labels_pred, train_labels_pred = train((train_loader, adj_matrices, labels_true))
TypeError: train() missing 1 required positional argument: 'dataset'

During handling of the above exception, another exception occurred:

Traceback (most recent call last):
  File "/usr/lib/python3.10/threading.py", line 1016, in _bootstrap_inner
    self.run()
  File "/usr/lib/python3.10/threading.py", line 953, in run
    self._target(*self._args, **self._kwargs)
  File "/home/users/yz705/.local/lib/python3.10/site-packages/wandb/agents/pyagent.py", line 312, in _run_job
    wandb.finish(exit_code=1)
  File "/home/users/yz705/.local/lib/python3.10/site-packages/wandb/sdk/wandb_run.py", line 4247, in finish
    wandb.run.finish(exit_code=exit_code, quiet=quiet)
  File "/home/users/yz705/.local/lib/python3.10/site-packages/wandb/sdk/wandb_run.py", line 449, in wrapper
    return func(self, *args, **kwargs)
  File "/home/users/yz705/.local/lib/python3.10/site-packages/wandb/sdk/wandb_run.py", line 390, in wrapper
    return func(self, *args, **kwargs)
  File "/home/users/yz705/.local/lib/python3.10/site-packages/wandb/sdk/wandb_run.py", line 2094, in finish
    return self._finish(exit_code, quiet)
  File "/home/users/yz705/.local/lib/python3.10/site-packages/wandb/sdk/wandb_run.py", line 2101, in _finish
    with telemetry.context(run=self) as tel:
  File "/home/users/yz705/.local/lib/python3.10/site-packages/wandb/sdk/lib/telemetry.py", line 42, in __exit__
    self._run._telemetry_callback(self._obj)
  File "/home/users/yz705/.local/lib/python3.10/site-packages/wandb/sdk/wandb_run.py", line 792, in _telemetry_callback
    self._telemetry_flush()
  File "/home/users/yz705/.local/lib/python3.10/site-packages/wandb/sdk/wandb_run.py", line 803, in _telemetry_flush
    self._backend.interface._publish_telemetry(self._telemetry_obj)
  File "/home/users/yz705/.local/lib/python3.10/site-packages/wandb/sdk/interface/interface_shared.py", line 101, in _publish_telemetry
    self._publish(rec)
  File "/home/users/yz705/.local/lib/python3.10/site-packages/wandb/sdk/interface/interface_sock.py", line 51, in _publish
    self._sock_client.send_record_publish(record)
  File "/home/users/yz705/.local/lib/python3.10/site-packages/wandb/sdk/lib/sock_client.py", line 221, in send_record_publish
    self.send_server_request(server_req)
  File "/home/users/yz705/.local/lib/python3.10/site-packages/wandb/sdk/lib/sock_client.py", line 155, in send_server_request
    self._send_message(msg)
  File "/home/users/yz705/.local/lib/python3.10/site-packages/wandb/sdk/lib/sock_client.py", line 152, in _send_message
    self._sendall_with_error_handle(header + data)
  File "/home/users/yz705/.local/lib/python3.10/site-packages/wandb/sdk/lib/sock_client.py", line 130, in _sendall_with_error_handle
    sent = self._sock.send(data)
BrokenPipeError: [Errno 32] Broken pipe
wandb: Sweep Agent: Waiting for job.
wandb: Job received.
wandb: Agent Starting Run: mxqm7du2 with config:
wandb: 	epochs: 80
wandb: 	lr: 1.018058894849886
wandb: 	new_adj_dim: 7
wandb: 	numSampledCCs: 5
wandb: 	numSampledCycles: 28
wandb: 	pretrain_epochs: 80
Exception in thread Thread-31 (_run_job):
Traceback (most recent call last):
  File "/home/users/yz705/.local/lib/python3.10/site-packages/wandb/agents/pyagent.py", line 307, in _run_job
    self._function()
  File "/usr/project/xtmp/yz705/deep-topological-clustering/./graph_autoencoder.py", line 409, in one_tune_instance
    pretrain_labels_pred, train_labels_pred = train((train_loader, adj_matrices, labels_true))
TypeError: train() missing 1 required positional argument: 'dataset'

During handling of the above exception, another exception occurred:

Traceback (most recent call last):
  File "/usr/lib/python3.10/threading.py", line 1016, in _bootstrap_inner
    self.run()
  File "/usr/lib/python3.10/threading.py", line 953, in run
    self._target(*self._args, **self._kwargs)
  File "/home/users/yz705/.local/lib/python3.10/site-packages/wandb/agents/pyagent.py", line 312, in _run_job
    wandb.finish(exit_code=1)
  File "/home/users/yz705/.local/lib/python3.10/site-packages/wandb/sdk/wandb_run.py", line 4247, in finish
    wandb.run.finish(exit_code=exit_code, quiet=quiet)
  File "/home/users/yz705/.local/lib/python3.10/site-packages/wandb/sdk/wandb_run.py", line 449, in wrapper
    return func(self, *args, **kwargs)
  File "/home/users/yz705/.local/lib/python3.10/site-packages/wandb/sdk/wandb_run.py", line 390, in wrapper
    return func(self, *args, **kwargs)
  File "/home/users/yz705/.local/lib/python3.10/site-packages/wandb/sdk/wandb_run.py", line 2094, in finish
    return self._finish(exit_code, quiet)
  File "/home/users/yz705/.local/lib/python3.10/site-packages/wandb/sdk/wandb_run.py", line 2101, in _finish
    with telemetry.context(run=self) as tel:
  File "/home/users/yz705/.local/lib/python3.10/site-packages/wandb/sdk/lib/telemetry.py", line 42, in __exit__
    self._run._telemetry_callback(self._obj)
  File "/home/users/yz705/.local/lib/python3.10/site-packages/wandb/sdk/wandb_run.py", line 792, in _telemetry_callback
    self._telemetry_flush()
  File "/home/users/yz705/.local/lib/python3.10/site-packages/wandb/sdk/wandb_run.py", line 803, in _telemetry_flush
    self._backend.interface._publish_telemetry(self._telemetry_obj)
  File "/home/users/yz705/.local/lib/python3.10/site-packages/wandb/sdk/interface/interface_shared.py", line 101, in _publish_telemetry
    self._publish(rec)
  File "/home/users/yz705/.local/lib/python3.10/site-packages/wandb/sdk/interface/interface_sock.py", line 51, in _publish
    self._sock_client.send_record_publish(record)
  File "/home/users/yz705/.local/lib/python3.10/site-packages/wandb/sdk/lib/sock_client.py", line 221, in send_record_publish
    self.send_server_request(server_req)
  File "/home/users/yz705/.local/lib/python3.10/site-packages/wandb/sdk/lib/sock_client.py", line 155, in send_server_request
    self._send_message(msg)
  File "/home/users/yz705/.local/lib/python3.10/site-packages/wandb/sdk/lib/sock_client.py", line 152, in _send_message
    self._sendall_with_error_handle(header + data)
  File "/home/users/yz705/.local/lib/python3.10/site-packages/wandb/sdk/lib/sock_client.py", line 130, in _sendall_with_error_handle
    sent = self._sock.send(data)
BrokenPipeError: [Errno 32] Broken pipe
wandb: Agent Starting Run: 0h2m5flf with config:
wandb: 	epochs: 70
wandb: 	lr: 1.0633176153433646
wandb: 	new_adj_dim: 12
wandb: 	numSampledCCs: 7
wandb: 	numSampledCycles: 47
wandb: 	pretrain_epochs: 30
Exception in thread Thread-32 (_run_job):
Traceback (most recent call last):
  File "/home/users/yz705/.local/lib/python3.10/site-packages/wandb/agents/pyagent.py", line 307, in _run_job
    self._function()
  File "/usr/project/xtmp/yz705/deep-topological-clustering/./graph_autoencoder.py", line 409, in one_tune_instance
    pretrain_labels_pred, train_labels_pred = train((train_loader, adj_matrices, labels_true))
TypeError: train() missing 1 required positional argument: 'dataset'

During handling of the above exception, another exception occurred:

Traceback (most recent call last):
  File "/usr/lib/python3.10/threading.py", line 1016, in _bootstrap_inner
    self.run()
  File "/usr/lib/python3.10/threading.py", line 953, in run
    self._target(*self._args, **self._kwargs)
  File "/home/users/yz705/.local/lib/python3.10/site-packages/wandb/agents/pyagent.py", line 312, in _run_job
    wandb.finish(exit_code=1)
  File "/home/users/yz705/.local/lib/python3.10/site-packages/wandb/sdk/wandb_run.py", line 4247, in finish
    wandb.run.finish(exit_code=exit_code, quiet=quiet)
  File "/home/users/yz705/.local/lib/python3.10/site-packages/wandb/sdk/wandb_run.py", line 449, in wrapper
    return func(self, *args, **kwargs)
  File "/home/users/yz705/.local/lib/python3.10/site-packages/wandb/sdk/wandb_run.py", line 390, in wrapper
    return func(self, *args, **kwargs)
  File "/home/users/yz705/.local/lib/python3.10/site-packages/wandb/sdk/wandb_run.py", line 2094, in finish
    return self._finish(exit_code, quiet)
  File "/home/users/yz705/.local/lib/python3.10/site-packages/wandb/sdk/wandb_run.py", line 2101, in _finish
    with telemetry.context(run=self) as tel:
  File "/home/users/yz705/.local/lib/python3.10/site-packages/wandb/sdk/lib/telemetry.py", line 42, in __exit__
    self._run._telemetry_callback(self._obj)
  File "/home/users/yz705/.local/lib/python3.10/site-packages/wandb/sdk/wandb_run.py", line 792, in _telemetry_callback
    self._telemetry_flush()
  File "/home/users/yz705/.local/lib/python3.10/site-packages/wandb/sdk/wandb_run.py", line 803, in _telemetry_flush
    self._backend.interface._publish_telemetry(self._telemetry_obj)
  File "/home/users/yz705/.local/lib/python3.10/site-packages/wandb/sdk/interface/interface_shared.py", line 101, in _publish_telemetry
    self._publish(rec)
  File "/home/users/yz705/.local/lib/python3.10/site-packages/wandb/sdk/interface/interface_sock.py", line 51, in _publish
    self._sock_client.send_record_publish(record)
  File "/home/users/yz705/.local/lib/python3.10/site-packages/wandb/sdk/lib/sock_client.py", line 221, in send_record_publish
    self.send_server_request(server_req)
  File "/home/users/yz705/.local/lib/python3.10/site-packages/wandb/sdk/lib/sock_client.py", line 155, in send_server_request
    self._send_message(msg)
  File "/home/users/yz705/.local/lib/python3.10/site-packages/wandb/sdk/lib/sock_client.py", line 152, in _send_message
    self._sendall_with_error_handle(header + data)
  File "/home/users/yz705/.local/lib/python3.10/site-packages/wandb/sdk/lib/sock_client.py", line 130, in _sendall_with_error_handle
    sent = self._sock.send(data)
BrokenPipeError: [Errno 32] Broken pipe
wandb: Sweep Agent: Waiting for job.
slurmstepd: error: *** JOB 2460000 ON linux55 CANCELLED AT 2024-06-20T22:55:35 ***
